Workbook

Sheet Index
B2: Bill Of Material (BOM)
B3: 1 | C3: Pregnancy Powder
B4: 2 | C4: Lactation Powder
B5: 3 | C5: Infant Formula Milk
B6: 4 | C6: Child Nutrition
B8: Profit & Loss Statement
B10: 22Cr Summary Sheet
B12: Year 1
B13: 1 | C13: 22Cr Capital Raised Working
B14: 2 | C14: Working Capital
B16: Year 2
B17: 1 | C17: 60Cr Capital Raised Working
B18: 2 | C18: Working Capital
B20: Year 3
B21: 1 | C21: Plant works @ 100% Efficiency
B22: 2 | C22: Working Capital

Sheet Infant Complementary BOM
B2: RAW MATERIAL COST
B4: Item No. | C4: Ingredient Name | D4: In Grams | F4: In Rupees
D5: Quantity Per 100 g | E5: Quantity per 400 gm | F5: Rate / Kg | G5: Rate / Gram | H5: Rate Per 400 g
B6: 1 | C6: Milk Solids | D6: 35 | E6: =D6*4 | F6: 240 | G6: =F6/1000 | H6: =E6*G6
B7: 2 | C7: Maltodextrin | D7: 20 | E7: =D7*4 | F7: 50 | G7: =F7/1000 | H7: =E7*G7
B8: 3 | C8: Sprouted Ragi Powder | D8: 13 | E8: =D8*4 | F8: 50 | G8: =F8/1000 | H8: =E8*G8
B9: 4 | C9: Rice Powder | D9: 10 | E9: =D9*4 | F9: 50 | G9: =F9/1000 | H9: =E9*G9
B10: 5 | C10: Apple Powder | D10: 8 | E10: =D10*4 | F10: 170 | G10: =F10/1000 | H10: =E10*G10
B11: 6 | C11: Enzyme(Alpha Amylase) | D11: 0.5 | E11: =D11*4 | F11: 1000 | G11: =F11/1000 | H11: =E11*G11
B12: 7 | C12: Fructooligosaccharides | D12: 7 | E12: =D12*4 | F12: 170 | G12: =F12/1000 | H12: =E12*G12
B13: 8 | C13: Mineral premix(Calcium, Phosphorous, Sodium, Potassium, Chloride, Magnesium, Iron, Zinc, Copper, Manganese, Iodine, Selenium) | D13: 1.88 | E13: =D13*4 | F13: 400 | G13: =F13/1000 | H13: =E13*G13
B14: 9 | C14: Vitamin premix(Vitamin A, D, E, K, C, B1, B2, B6, B12, B7,B5, B3) | D14: 0.05 | E14: =D14*4 | F14: 500 | G14: =F14/1000 | H14: =E14*G14
B15: 10 | C15: Jaggery Powder | D15: 5 | E15: =D15*4 | F15: 60 | G15: =F15/1000 | H15: =E15*G15
B16: RAW MATERIAL TOTAL COST | D16: =SUM(D6:D15) | E16: =D16*4 | H16: =SUM(H6:H14)
B18: OTHER COSTS
C20: Packaging | H20: 12
C21: Conversion | H21: 30
F23: TOTAL COST / BOX | H23: =H16+H20+H21
F25: PRODUCTION COST / BATCH | H25: 20000000
F27: BOXES / BATCH | H27: =H25/H23
F29: BOXES / VARIANT | H29: =H27/3
F31: AS PER PROJETIONS SHEET
F32: Total Cost (Excl. GST) | H32: 111 | I32: VS | J32: =H23
F33: GST 18% | H33: 16
F34: Total Cost (Incl. GST) | H34: 127

Sheet Total Production
A1: VALENCIA NUTRACARE LIFESCIENCES (Consumer Validation)
B3: EARLY STAGE FUND | C3: Natal Care | D3: Infant & Child Nutrition | E3: Total
B4: Funding (₹ Cr) | C4: 11 | D4: 11 | E4: =C4+D4
B5: Production (₹ Cr) | C5: 8 | D5: 8 | E5: =C5+D5 | F5: * 2 cycles of production
B6: Admin & Marketing Exp (₹ Cr) | C6: 3 | D6: 3 | E6: =C6+D6
C8: Pregnancy Powder (Garbhika) | D8: Lactation Powder (Matrusneha) | E8: Infant Formula Milk Powder (Poshit) | F8: Child Nutrition Powder
B9: Cost/Box | C9: ='PP BOM'!H25 | D9: ='LP BOM'!H28 | E9: ='IFM BOM'!H30 | F9: ='CNP BOM'!H24
B10: Production Cost/Batch | C10: ='PP BOM'!H27 | D10: ='LP BOM'!H30 | E10: ='IFM BOM'!H32 | F10: ='CNP BOM'!H26
B11: Boxes/Batch | C11: =Round(C10/C9,0) | D11: =Round(D10/D9,0) | E11: =Round(E10/E9,0) | F11: =Round(F10/F9,0)
B13: TOTAL BOXES | C13: =C11+D11+E11+F11
B15: AVERAGE BOXES/VARIANT | C15: =average(C11:F11)
B17: AVERAGE COST/BOX | C17: =average(C9:F9)
B19: Products | C19: Selling Price (in ₹) | D19: Boxes/Batch | E19: Revenue / Batch (in ₹) | F19: COGS / Batch (in ₹) | G19: Gross Profit/ Batch (in ₹)
B20: Pregnancy Powder | C20: 280 | D20: =C11 | E20: =C20*D20 | F20: =D20*C9 | G20: =E20-F20
B21: Lactation Powder | C21: 286 | D21: =D11 | E21: =C21*D21 | F21: =D21*D9 | G21: =E21-F21
B22: Infant Formula Milk Powder | C22: 242 | D22: =E11 | E22: =C22*E11 | F22: =D22*E9 | G22: =E22-F22
B23: Child Nutrition Powder | C23: 212 | D23: =F11 | E23: =C23*F11 | F23: =D23*F9 | G23: =E23-F23
D24: TOTAL (in ₹) | E24: =SUM(E20:E23) | F24: =SUM(F20:F23) | G24: =SUM(G20:G23)
D25: TOTAL (₹ in Cr) | E25: =E24/10^7 | F25: =F24/10^7 | G25: =G24/10^7
B28: Amount in ₹ Cr
B29: Gross Profit | C29: =G25
B30: Marketing Expense | C30: =E6/2
B31: EBITDA | C31: =C29-C30
B33: Remaining Funds | C33: =(E5+E6)/2 | D33: * 8cr for Production, 3cr for Marketing Expense
B34: Production Funds for Batch 2 | C34: =C31+(E5/2)
B36: Maketing Funds for Batch 2 | C36: =E6/2
B38: TRIO FIT WORKING CAPACITY
C39: 1 day | D39: Working Efficiency | F39: Bulk density | G39: Manufacturing | H39: 1 day
B40: Blender | C40: 500l | D40: 0.7 | E40: =1200 | F40: 0.4 | G40: 400kg/5 hrs | H40: 800kg
B41: Blender 1 | C41: 1500 | D41: 0.7
B42: Blender 2 | C42: =300 | D42: 0.7 | G42: 100kg/5hrs | H42: 200kg
C44: PP | D44: LP | E44: IFP | F44: CNP
B45: Kgs to be Manufactured | C45: =C11*0.5 | D45: =D11*0.5 | E45: =(E11*400)/1000 | F45: =(F11*400)/1000 | G45: * 1 batch capacity
B46: Tons to be Manufactured | C46: =C45/1000 | D46: =D45/1000 | E46: =E45/1000 | F46: =F45/1000
C48: Total Production Capacity | D48: Days | E48: Months (25 days working)
C49: =2*300*1000 | D49: 300 | E49: =D49/25
C50: =sum(C45:F45) | D50: =(C50*D49)/C49 | E50: =D50/25
C52: 1 DAY PRODUCTION CAPACITY (Rohan sir's factory)
C53: PP | D53: LP | E53: IFP | F53: CNP
B54: Boxes | C54: =C55*2 | D54: =D55*2 | E54: =(E55*1000)/400 | F54: =(F55*1000)/400 | G54: =SUM(C54:F54)
...

Sheet Year 2
B2: YEAR 2 FUNDING (in Cr) | C2: 60
C4: Pregnancy Powder (Garbhika) | D4: Lactation Powder (Matrusneha) | E4: Infant Formula Milk Powder (Poshit) | F4: Child Nutrition Powder
B5: Cost/Box | C5: ='PP BOM'!H32 | D5: ='LP BOM'!H35 | E5: ='IFM BOM'!H39 | F5: ='CNP BOM'!H31
B6: Selling Price/Box | C6: ='Total Production'!C20 | D6: ='Total Production'!C21 | E6: ='Total Production'!C22 | F6: ='Total Production'!C23
B7: Profit/Box | C7: =C6-C5 | D7: =D6-D5 | E7: =E6-E5 | F7: =F6-F5
B9: Taking into consideration the following information:
B10: Tons Manufactured / Day | C10: 40 | D10: * 2 tons a day at Rohan Sir's Factory (Natal Care only). Assuming another factory will have 2 tons too
B11: Kgs Manufactured / Day | C11: =C10*1000
B12: Boxes Manufactured / Day | C12: =((C11*1000*0.5)/500)+((C11*1000*0.5)/400)
B14: Natal Care Boxes/Day | C14: =((C11*1000*0.5)/500)*C76 | D14: * Natal Care Products are 500gms each
B15: Infant & Child Care Boxes/Day | C15: =((C11*1000*0.5)/400)*C76 | D15: * Infant and Child Care Products are 400gms each
B17: Working Days/Month | C17: 25
B18: Working Months/Year | C18: 12
B19: Working Days/Year | C19: =C17*C18
B21: PRODUCTION
B22: Products | C22: Boxes/Year | D22: Revenue/Year | E22: Revenue (in Cr) | F22: COGS (in Cr) | G22: Gross Profit (in Cr)
B23: Infant Formula Milk | C23: =($C$19*$C$15)/2 | D23: =C23*E6 | E23: =D23/10^7 | F23: =(C23*E5)/10^7 | G23: =E23-F23
B24: Child Nutrition Powder | C24: =($C$19*$C$15)/2 | D24: =C24*F6 | E24: =D24/10^7 | F24: =(C24*F5)/10^7 | G24: =E24-F24
B25: Pregnancy Powder | C25: =($C$19*$C$14)/2 | D25: =C25*C6 | E25: =D25/10^7 | F25: =(C25*C5)/10^7 | G25: =E25-F25
B26: Lactation Powder | C26: =($C$19*$C$14)/2 | D26: =C26*D6 | E26: =D26/10^7 | F26: =(C26*D5)/10^7 | G26: =E26-F26
C27: =sum(C23:C26) | E27: =sum(E23:E26) | F27: =sum(F23:F26) | G27: =sum(G23:G26)
B29: WORKING CAPITAL
C30: Year 1 | D30: Year 2 | E30: Fresh Capital Needed
B31: Working Capital (in Cr) | C31: ='Contract (1 yr)'!C30 | D31: ='WC (Year 3-5)'!D17/10^7 | E31: =D31-C31
B32: Pregnancy Powder (in Cr) | C32: ='Contract (1 yr)'!C31 | D32: ='WC (Year 3-5)'!D5/10^7 | E32: =D32-C32
B33: Lactation Powder (in Cr) | C33: ='Contract (1 yr)'!C32 | D33: ='WC (Year 3-5)'!D8/10^7 | E33: =D33-C33
B34: Infant Formula Milk (in Cr) | C34: ='Contract (1 yr)'!C33 | D34: ='WC (Year 3-5)'!D11/10^7 | E34: =D34-C34
B35: Child Nutrition Powder (in Cr) | C35: ='Contract (1 yr)'!C34 | D35: ='WC (Year 3-5)'!D14/10^7 | E35: =D35-C35
B37: APPLICATION & SOURCES OF FUND
B38: Sources of Fund | C38: =C42
B39: A. VNL | C39: =C38-C40-C41
B40: B. Capital Raise | C40: =C2
B41: C. Existing Working Capital | C41: =C31
B42: Application of Fund | C42: =sum(C43:C45)
B43: A. Production | C43: ='WC (Year 3-5)'!H17/10^7
B44: B. Indirect Expense | C44: ='WC (Year 3-5)'!I17/10^7
B45: C. Plant CAPEX | C45: =C64
B47: CAPEX TABLE
B48: Cost of Project | C48: Cost (in Cr)
B49: Land and Plant Building | C49: ='Capex & Depreciation'!C26
...

Sheet Year 3
B2: YEAR 3 FUNDING (in Cr) | C2: 0
C4: Pregnancy Powder (Garbhika) | D4: Lactation Powder (Matrusneha) | E4: Infant Formula Milk Powder (Poshit) | F4: Child Nutrition Powder
B5: Cost/Box | C5: ='PP BOM'!H32 | D5: ='LP BOM'!H35 | E5: ='IFM BOM'!H39 | F5: ='CNP BOM'!H31
B6: Selling Price/Box | C6: ='Total Production'!C20 | D6: ='Total Production'!C21 | E6: ='Total Production'!C22 | F6: ='Total Production'!C23
B7: Profit/Box | C7: =C6-C5 | D7: =D6-D5 | E7: =E6-E5 | F7: =F6-F5
B9: Taking into consideration the following information:
B10: Tons Manufactured / Day | C10: 40 | D10: * 2 tons a day at Rohan Sir's Factory (Natal Care only). Assuming another factory will have 2 tons too
B11: Kgs Manufactured / Day | C11: =C10*1000
B12: Boxes Manufactured / Day | C12: =((C11*1000*0.5)/500)+((C11*1000*0.5)/400)
B14: Natal Care Boxes/Day | C14: =((C11*1000*0.5)/500)*C75 | D14: * Natal Care Products are 500gms each
B15: Infant & Child Care Boxes/Day | C15: =((C11*1000*0.5)/400)*C75 | D15: * Infant and Child Care Products are 400gms each
B17: Working Days/Month | C17: 25
B18: Working Months/Year | C18: 12
B19: Working Days/Year | C19: =C17*C18
B21: PRODUCTION
B22: Products | C22: Boxes/Year | D22: Revenue/Year | E22: Revenue (in Cr) | F22: COGS (in Cr) | G22: Gross Profit (in Cr)
B23: Infant Formula Milk | C23: =($C$19*$C$15)/2 | D23: =C23*E6 | E23: =D23/10^7 | F23: =(C23*E5)/10^7 | G23: =E23-F23
B24: Child Nutrition Powder | C24: =($C$19*$C$15)/2 | D24: =C24*F6 | E24: =D24/10^7 | F24: =(C24*F5)/10^7 | G24: =E24-F24
B25: Pregnancy Powder | C25: =($C$19*$C$14)/2 | D25: =C25*C6 | E25: =D25/10^7 | F25: =(C25*C5)/10^7 | G25: =E25-F25
B26: Lactation Powder | C26: =($C$19*$C$14)/2 | D26: =C26*D6 | E26: =D26/10^7 | F26: =(C26*D5)/10^7 | G26: =E26-F26
C27: =sum(C23:C26) | E27: =sum(E23:E26) | F27: =sum(F23:F26) | G27: =sum(G23:G26)
B29: WORKING CAPITAL
C30: Year 3 | D30: Year 2 | E30: Fresh Capital Needed
B31: Working Capital (in Cr) | C31: ='WC (Year 3)'!D9/10^7 | D31: ='Year 2'!D31 | E31: =C31-D31
B32: Pregnancy Powder (in Cr) | C32: ='WC (Year 3)'!D5/10^7 | D32: ='WC (Year 3-5)'!D5/10^7 | E32: =C32-D32
B33: Lactation Powder (in Cr) | C33: ='WC (Year 3)'!D6/10^7 | D33: ='WC (Year 3-5)'!D8/10^7 | E33: =C33-D33
B34: Infant Formula Milk (in Cr) | C34: ='WC (Year 3)'!D7/10^7 | D34: ='WC (Year 3-5)'!D11/10^7 | E34: =C34-D34
B35: Child Nutrition Powder (in Cr) | C35: ='WC (Year 3)'!D8/10^7 | D35: ='WC (Year 3-5)'!D14/10^7 | E35: =C35-D35
B37: APPLICATION & SOURCES OF FUND
B38: Sources of Fund | C38: =C42
B39: A. VNL Retained Earnings | C39: =C38-C40-C41 | D39: * 7.58% of Retained Earnings
B40: B. Capital Raise | C40: =C2
B41: C. Existing Working Capital | C41: =D31
B42: Application of Fund | C42: =sum(C43:C44)
B43: A. Production | C43: ='WC (Year 3)'!H9/10^7
B44: B. Indirect Expense | C44: ='WC (Year 3)'!I9/10^7
B46: CAPEX TABLE
B47: Cost of Project | C47: Cost (in Cr)
B48: Land and Plant Building | C48: ='Capex & Depreciation'!C26
B49: Utilities (Power, Tanks etc.)
...

Sheet WC (Year 3)
B2: TOTAL WORKING CAPITAL | G2: APPLICATION OF FUNDS
C4: Revenue | D4: Initial Working Capital | E4: W.C.Rotation | H4: Production | I4: Indirect Expense
B5: PP | C5: =D35 | D5: =D36 | E5: =IFERROR(C5/D5,0) | G5: PP | H5: =(D13*D14)*2.5 | I5: =D16*2.5
B6: LP | C6: =D64 | D6: =D65 | E6: =IFERROR(C6/D6,0) | G6: LP | H6: =(D42*D43)*2.5 | I6: =D45*2.5
B7: IFP | C7: =D93 | D7: =D94 | E7: =IFERROR(C7/D7,0) | G7: IFP | H7: =(D71*D72)*2.5 | I7: =D74*2.5
B8: CNP | C8: =D122 | D8: =D123 | E8: =IFERROR(C8/D8,0) | G8: CNP | H8: =(D100*D101)*2.5 | I8: =D103*2.5
D9: =sum(D5:D8) | H9: =sum(H5:H8) | I9: =sum(I5:I8)
H10: =H9+I9
B11: PREGNANCY POWDER
B13: Monthly Boxes Produced (in Units) | D13: ='Year 3'!C25/12
B14: Cost/Box (in ₹) | D14: ='Year 2'!C5
B15: Revenue/Box (in ₹) | D15: ='Year 2'!C6
B16: Monthly Indirect Expense (in ₹) | D16: =('Year 2'!$E$88/12)/4
G17: * The working capital that we are investing in the first month is derived from the cash outflow that is required in the first month
B18: Month | C18: Cash Outflow | D18: Cash Inflow | E18: Difference (CO-CI) | G18: Opening W.C. | H18: Net Cash Flow | I18: Closing W.C.
B19: April | C19: =($D$13*$D$14)+$D$16 | D19: =$D$13*$D$15 | E19: =D19-C19 | G19: =C19+D33 | H19: =E19 | I19: =G19+H19
B20: May | C20: =($D$13*$D$14)+$D$16 | D20: =$D$13*$D$15 | E20: =D20-C20 | G20: =I19 | H20: =E20 | I20: =G20+H20
B21: June | C21: =($D$13*$D$14)+$D$16 | D21: =$D$13*$D$15 | E21: =D21-C21 | G21: =I20 | H21: =E21 | I21: =G21+H21
B22: July | C22: =($D$13*$D$14)+$D$16 | D22: =$D$13*$D$15 | E22: =D22-C22 | G22: =I21 | H22: =E22 | I22: =G22+H22
B23: August | C23: =($D$13*$D$14)+$D$16 | D23: =$D$13*$D$15 | E23: =D23-C23 | G23: =I22 | H23: =E23 | I23: =G23+H23
B24: September | C24: =($D$13*$D$14)+$D$16 | D24: =$D$13*$D$15 | E24: =D24-C24 | G24: =I23 | H24: =E24 | I24: =G24+H24
B25: October | C25: =($D$13*$D$14)+$D$16 | D25: =$D$13*$D$15 | E25: =D25-C25 | G25: =I24 | H25: =E25 | I25: =G25+H25
B26: November | C26: =($D$13*$D$14)+$D$16 | D26: =$D$13*$D$15 | E26: =D26-C26 | G26: =I25 | H26: =E26 | I26: =G26+H26
B27: December | C27: =($D$13*$D$14)+$D$16 | D27: =$D$13*$D$15 | E27: =D27-C27 | G27: =I26 | H27: =E27 | I27: =G27+H27
B28: January | C28: =($D$13*$D$14)+$D$16 | D28: =$D$13*$D$15 | E28: =D28-C28 | G28: =I27 | H28: =E28 | I28: =G28+H28
B29: February | C29: =($D$13*$D$14)+$D$16 | D29: =$D$13*$D$15 | E29: =D29-C29 | G29: =I28 | H29: =E29 | I29: =G29+H29
B30: March | C30: =($D$13*$D$14)+$D$16 | D30: =$D$13*$D$15 | E30: =D30-C30 | G30: =I29 | H30: =E30 | I30: =G30+H30
C31: =SUM(C19:C30) | D31: =SUM(D19:D30) | E31: =D31-C31
B33: Buffer Capital (Production Cost of 1.5 Months) | D33: =C19*1.5
B35: Total Yearly Turnover | D35: =D31
B36: Initial Working Capital | D36: =C19+D33 | E36: * Working Capital Required=Cash outflow for the first month + Contingency fund
B37: Working Capital Rotation | D37: =IFERROR(D35/D36,0)
B40: LACTATION POWDER
B42: Monthly Boxes Produced (in Units) | D42: ='Year 3'!C26/12
B43: Cost/Box (in ₹) | D43: ='Year 2'!D5
B44: Revenue/Box (in ₹) | D44: ='Year 2'!D6
B45: Monthly Indirect Expense (in ₹) | D45: =('Year 2'!$E$88/12)/4
G46: * The working capital that we are investing in the first month is derived from the cash outflow that is required in the first month
B47: Month | C47: Cash Outflow | D47: Cash Inflow | E47: Difference (CO-CI) | G47: Opening W.C. | H47: Net Cash Flow | I47: Closing W.C.
B48: April | C48: =($D$42*$D$43)+$D$45 | D48: =$D$42*$D$44 | E48: =D48-C48 | G48: =C48+D62 | H48: =E48 | I48: =G48+H48
...

Sheet PP BOM
B2: RAW MATERIAL COST
B4: Item No. | C4: Ingredient Name | D4: In Grams | F4: In Rupees
D5: Quantity Per 100 g | E5: Quantity per 500 gm | F5: Rate / Kg | G5: Rate / Gram | H5: Rate Per 500 g
B6: 1 | C6: Skimmed Milk Powder | D6: 35 | E6: =D6*5 | F6: 320 | G6: =F6/1000 | H6: =E6*G6
B7: 2 | C7: Maltodextrin | D7: 23.84 | E7: =D7*5 | F7: 70 | G7: =F7/1000 | H7: =E7*G7
B8: 3 | C8: Fructooligosaccharides | D8: 5 | E8: =D8*5 | F8: 170 | G8: =F8/1000 | H8: =E8*G8
B9: 4 | C9: Rice Protein | D9: 7 | E9: =D9*5 | F9: 270 | G9: =F9/1000 | H9: =E9*G9
B10: 5 | C10: Soy Protein | D10: 13 | E10: =D10*5 | F10: 290 | G10: =F10/1000 | H10: =E10*G10
B11: 6 | C11: Shingada Flour | D11: 2 | E11: =D11*5 | F11: 190 | G11: =F11/1000 | H11: =E11*G11
B12: 7 | C12: Cocoa Powder | D12: 8 | E12: =D12*5 | F12: 600 | G12: =F12/1000 | H12: =E12*G12 | I12: 1 | J12: KESAR PISTA
B13: 8 | C13: Vitamin and Mineral Premix | D13: 3.5 | E13: =D13*5 | F13: 850 | G13: =F13/1000 | H13: =E13*G13 | I13: 2 | J13: CHOCOLATE
B14: 9 | C14: Culture | D14: 0.1 | E14: =D14*5 | F14: 480 | G14: =F14/1000 | H14: =E14*G14
B15: 10 | C15: Sucralose | D15: 0.06 | E15: =D15*5 | F15: 1450 | G15: =F15/1000 | H15: =E15*G15
B16: 11 | C16: Nature Identical Flavour | D16: 2 | E16: =D16*5 | F16: 700 | G16: =F16/1000 | H16: =E16*G16 | J16: KG | K16: BOXES | L16: COST
B17: 12 | C17: Multisense | D17: 0.5 | E17: =D17*5 | F17: 2500 | G17: =F17/1000 | H17: =E17*G17 | J17: =(K17*500)/1000 | K17: 800 | L17: =K17*H25 | M17: COGS_ Preg
D18: =SUM(D6:D17) | E18: =SUM(E6:E17) | H18: =SUM(H6:H17) | J18: =(K18*500)/1000 | K18: 800 | L18: =K18*'LP BOM'!H28 | M18: COGS_Lact
J19: =J17+J18 | K19: =K17+K18 | L19: =L17+L18 | M19: TOTAL
B20: OTHER COSTS
C22: Packaging cost | H22: 20
C23: Conversion cost | H23: ='Contract (1 yr)'!C43
F25: TOTAL COST / BOX | H25: =SUM(H18:H23)
F27: COST / BATCH | H27: 20000000
F29: BOXES / BATCH | H29: =H27/H25
F31: AS PER PROJETIONS SHEET
F32: Total Cost (Excl. GST) | H32: =H25 | I32: VS | J32: =H25
F33: GST 18%
F34: Total Cost (Incl. GST)
B37: Mawa Kulfi
B38: Item No. | C38: Ingredient Name | D38: In Grams | F38: In Rupees
D39: Quantity Per 100 g | E39: Quantity per 500 gm | F39: Rate / Kg | G39: Rate / Gram | H39: Rate Per 500 g
B40: 1 | C40: Skimmed Milk Powder | D40: 36 | E40: =D40*5 | F40: 240 | G40: =F40/1000 | H40: =E40*G40
B41: 2 | C41: Maltodextrin | D41: 27.84 | E41: =D41*5 | F41: 70 | G41: =F41/1000 | H41: =E41*G41
B42: 3 | C42: Fructooligosaccharides | D42: 5 | E42: =D42*5 | F42: 170 | G42: =F42/1000 | H42: =E42*G42
B43: 4 | C43: Rice Protein | D43: 8 | E43: =D43*5 | F43: 270 | G43: =F43/1000 | H43: =E43*G43
B44: 5 | C44: Soy Protein | D44: 15 | E44: =D44*5 | F44: 290 | G44: =F44/1000 | H44: =E44*G44
B45: 6 | C45: Shingada Flour | D45: 2 | E45: =D45*5 | F45: 190 | G45: =F45/1000 | H45: =E45*G45
B46: 7 | D46: 0 | E46: =D46*5 | F46: 600 | G46: =F46/1000 | H46: =E46*G46
B47: 8 | C47: Vitamin and Mineral Premix | D47: 3.5 | E47: =D47*5 | F47: 850 | G47: =F47/1000 | H47: =E47*G47
B48: 9 | C48: Culture | D48: 0.1 | E48: =D48*5 | F48: 480 | G48: =F48/1000 | H48: =E48*G48
B49: 10 | C49: Sucralose | D49: 0.06 | E49: =D49*5 | F49: 1300 | G49: =F49/1000 | H49: =E49*G49
...

Sheet LP BOM
B2: RAW MATERIAL COST
B4: Item No. | C4: Ingredient Name | D4: In Grams | F4: In Rupees
D5: Quantity Per 100 g | E5: Quantity per 500 gm | F5: Rate / Kg | G5: Rate / Gram | H5: Rate Per 500 g
B6: 1 | C6: Skimmed Milk Powder | D6: 35.5 | E6: =D6*5 | F6: 320 | G6: =F6/1000 | H6: =E6*G6
B7: 2 | C7: Maltodextrin | D7: 24.85 | E7: =D7*5 | F7: 70 | G7: =F7/1000 | H7: =E7*G7
B8: 3 | C8: Fructooligosaccharides | D8: 5 | E8: =D8*5 | F8: 170 | G8: =F8/1000 | H8: =E8*G8
B9: 4 | C9: Rice Protein | D9: 8 | E9: =D9*5 | F9: 270 | G9: =F9/1000 | H9: =E9*G9 | I9: 1 | J9: MAWA KULFI
B10: 5 | C10: Soy Protein | D10: 15 | E10: =D10*5 | F10: 290 | G10: =F10/1000 | H10: =E10*G10 | I10: 2 | J10: VANILA
B11: 6 | C11: Shingada Flour | D11: 2 | E11: =D11*5 | F11: 180 | G11: =F11/1000 | H11: =E11*G11
B12: 7 | C12: Vitamin and Mineral premix | D12: 3.5 | E12: =D12*5 | F12: 800 | G12: =F12/1000 | H12: =E12*G12
B13: 8 | C13: Culture | D13: 0.1 | E13: =D13*5 | F13: 450 | G13: =F13/1000 | H13: =E13*G13
B14: 9 | C14: Sucralose | D14: 0.05 | E14: =D14*5 | F14: 1450 | G14: =F14/1000 | H14: =E14*G14
B15: 10 | C15: Nature Identical Flavour Cardamom | D15: 1.5 | E15: =D15*5 | F15: 700 | G15: =F15/1000 | H15: =E15*G15
B16: 11 | C16: Shatavari | D16: 2 | E16: =D16*5 | F16: 350 | G16: =F16/1000 | H16: =E16*G16
B17: 12 | C17: Ashwagandha | D17: 1 | E17: =D17*5 | F17: 650 | G17: =F17/1000 | H17: =E17*G17
B18: 13 | C18: Moringa | D18: 0.5 | E18: =D18*5 | F18: 180 | G18: =F18/1000 | H18: =E18*G18
B19: 14 | C19: Funnel | D19: 0.5 | E19: =D19*5 | F19: 180 | G19: =F19/1000 | H19: =E19*G19
B20: 15 | C20: Cinnamon | D20: 0.5 | E20: =D20*5 | F20: 100 | G20: =F20/1000 | H20: =E20*G20
D21: =SUM(D6:D20) | E21: =SUM(E6:E20) | H21: =SUM(H6:H20)
B23: OTHER COSTS
C25: Packaging cost | H25: 20
C26: Conversion cost | H26: ='Contract (1 yr)'!C43
F28: TOTAL COST / BOX | H28: =sum(H21:H26) | K28: =H28*800 | L28: - COST OF 400 Boxes
F30: PRODUCTION COST / BATCH | H30: 20000000
F32: BOXES / BATCH | H32: =H30/H28
F34: AS PER PROJETIONS SHEET
F35: Total Cost (Excl. GST) | H35: =H28 | I35: VS | J35: =H28
F36: GST 18%
F37: Total Cost (Incl. GST)
C39: Kesar
B40: Item No. | C40: Ingredient Name | D40: In Grams | F40: In Rupees
D41: Quantity Per 100 g | E41: Quantity per 500 gm | F41: Rate / Kg | G41: Rate / Gram | H41: Rate Per 500 g
B42: 1 | C42: Skimmed Milk Powder | D42: 35 | E42: =D42*5 | F42: 240 | G42: =F42/1000 | H42: =E42*G42
B43: 2 | C43: Maltodextrin | D43: 25 | E43: =D43*5 | F43: 50 | G43: =F43/1000 | H43: =E43*G43
B44: 3 | C44: Fructooligosaccharides | D44: 5 | E44: =D44*5 | F44: 170 | G44: =F44/1000 | H44: =E44*G44
B45: 4 | C45: Rice Protein | D45: 8.35 | E45: =D45*5 | F45: 270 | G45: =F45/1000 | H45: =E45*G45
B46: 5 | C46: Soy Protein | D46: 15 | E46: =D46*5 | F46: 290 | G46: =F46/1000 | H46: =E46*G46
B47: 6 | C47: Shingada Flour | D47: 2 | E47: =D47*5 | F47: 180 | G47: =F47/1000 | H47: =E47*G47
B48: 7 | C48: Vitamin and Mineral premix | D48: 3.5 | E48: =D48*5 | F48: 800 | G48: =F48/1000 | H48: =E48*G48
B49: 8 | C49: Culture | D49: 0.1 | E49: =D49*5 | F49: 450 | G49: =F49/1000 | H49: =E49*G49
...

Sheet IFM BOM
B2: RAW MATERIAL COST
B4: Item No. | C4: Ingredient Name | D4: In Grams | F4: In Rupees
D5: Quantity Per 100 g | E5: Quantity per 400 gm | F5: Rate / Kg | G5: Rate / Gram | H5: Rate Per 400 g
B6: 1 | C6: Skim Milk Powder | D6: 35 | E6: =D6*4 | F6: 320 | G6: =F6/1000 | H6: =E6*G6
B7: 2 | C7: Demineralised Whey Powder | D7: 22 | E7: =D7*4 | F7: 150 | G7: =F7/1000 | H7: =E7*G7
B8: 3 | C8: Lactose | D8: 13 | E8: =D8*4 | F8: 200 | G8: =F8/1000 | H8: =E8*G8
B9: 4 | C9: Maltodextrin | D9: 8.05 | E9: =D9*4 | F9: 70 | G9: =F9/1000 | H9: =E9*G9
B10: 5 | C10: High Oleic Sunflower Oil | D10: 6 | E10: =D10*4 | F10: 350 | G10: =F10/1000 | H10: =E10*G10
B11: 6 | C11: Soya oil Powder | D11: 4 | E11: =D11*4 | F11: 100 | G11: =F11/1000 | H11: =E11*G11
B12: 7 | C12: Coconut oil Powder | D12: 2 | E12: =D12*4 | F12: 250 | G12: =F12/1000 | H12: =E12*G12
B13: 8 | C13: Milk fat powder | D13: 4 | E13: =D13*4 | F13: 230 | G13: =F13/1000 | H13: =E13*G13
B14: 9 | C14: DHA oil Powder | D14: 0.2 | E14: =D14*4 | F14: 400 | G14: =F14/1000 | H14: =E14*G14
B15: 10 | C15: ARA oil Powder | D15: 0.2 | E15: =D15*4 | F15: 150 | G15: =F15/1000 | H15: =E15*G15
B16: 11 | C16: Fructooligosaccharides | D16: 2 | E16: =D16*4 | F16: 170 | G16: =F16/1000 | H16: =E16*G16
B17: 12 | C17: Galactooligosaccharides | D17: 1.5 | E17: =D17*4 | F17: 200 | G17: =F17/1000 | H17: =E17*G17
... B22: 17 | C22: L-Carnitine | D22: 0.05 | E22: =D22*4 | F22: 2000 | G22: =F22/1000 | H22: =E22*G22
B23: RAW MATERIAL TOTAL COST | D23: =SUM(D6:D22) | E23: =D23*5 | H23: =SUM(H6:H22)
B25: OTHER COSTS
C27: Packaging | H27: 20
C28: Conversion | H28: ='Contract (1 yr)'!C51
F30: TOTAL COST / BOX | H30: =H23+H27+H28
F32: PRODUCTION COST / BATCH | H32: 20000000
F34: BOXES / BATCH | H34: =H32/H30
F36: BOXES / VARIANT | H36: =H34/3
F38: AS PER PROJETIONS SHEET
F39: Total Cost (Excl. GST) | H39: =H30 | I39: VS | J39: =H30
F40: GST 18%
F41: Total Cost (Incl. GST)

Sheet CNP BOM
B2: RAW MATERIAL COST
B4: Item No. | C4: Ingredient Name | D4: In Grams | F4: In Rupees
D5: Quantity Per 100 g | E5: Quantity per 400 gm | F5: Rate / Kg | G5: Rate / Gram | H5: Rate Per 400 g
B6: 1 | C6: Skimmed Milk Powder | D6: 35 | E6: =D6*4 | F6: 320 | G6: =F6/1000 | H6: =E6*G6
B7: 2 | C7: Maltodextrin | D7: 14 | E7: =D7*4 | F7: 70 | G7: =F7/1000 | H7: =E7*G7
B8: 3 | C8: Nuts blend(Almond, Cashew, Walnut, Pista, Dates) | D8: 6 | E8: =D8*4 | F8: 180 | G8: =F8/1000 | H8: =E8*G8
B9: 4 | C9: Cocoa powder | D9: 6 | E9: =D9*4 | F9: 600 | G9: =F9/1000 | H9: =E9*G9 | I9: 1 | J9: VANILLA
B10: 5 | C10: Palmyra Jaggery | D10: 13 | E10: =D10*4 | F10: 50 | G10: =F10/1000 | H10: =E10*G10 | I10: 2 | J10: CHOCOLATE
B11: 6 | C11: Fructooligosaccharides | D11: 2 | E11: =D11*4 | F11: 170 | G11: =F11/1000 | H11: =E11*G11
B12: 7 | C12: Nature Identical Flavours | D12: 2 | E12: =D12*4 | F12: 600 | G12: =F12/1000 | H12: =E12*G12
B13: 8 | C13: Vitamins | D13: 1 | E13: =D13*4 | F13: 500 | G13: =F13/1000 | H13: =E13*G13
B14: 9 | C14: Minerals | D14: 1 | E14: =D14*4 | F14: 400 | G14: =F14/1000 | H14: =E14*G14
B15: 10 | C15: Fruit Powder | D15: 12 | E15: =D15*4 | F15: 200 | G15: =F15/1000 | H15: =E15*G15
B16: 11 | C16: Ragi Powder | D16: 8 | E16: =D16*4 | F16: 40 | G16: =F16/1000 | H16: =E16*G16
D17: =SUM(D6:D16) | E17: =D17*4 | H17: =SUM(H6:H16)
B19: OTHER COSTS
C21: Packaging Cost | H21: 20
C22: Conversion cost | H22: ='Contract (1 yr)'!C51
F24: TOTAL COST / BOX | H24: =sum(H17:H22)
F26: PRODUCTION COST / BATCH | H26: 20000000
F28: BOXES / BATCH | H28: =H26/H24
F30: AS PER PROJETIONS SHEET
F31: Total Cost (Excl. GST) | H31: =H24 | I31: VS | J31: =H24
F32: GST 18%
F33: Total Cost (Incl. GST)

Sheet Product Line
B2: * SKUs may vary from year to year due to addition of new flavours (Currently 1-2 flavours of each Variant)
B3: Years | C3: All Products | D3: Tier
B4: Year 1 | C4: 4
C5: Pregnancy Powder | D5: 3
C6: Lactation Powder | D6: 3
C7: Infant Powder | D7: 3
C8: Children Powder | D8: 3
B10: Year 2 | C10: =COUNTA(C11:C24)
C11: Pregnancy Powder- Trimester 1 | D11: 1
C12: Pregnancy Powder- Trimester 2 | D12: 1
C13: Pregnancy Powder- Trimester 3 | D13: 1
C14: Lactation Powder | D14: 1
C15: Infant Formula Powder- 0 to 6m | D15: 1
C16: Infant Formula Powder- 6 to 12m | D16: 1
C17: Infant Formula Powder- 12 to 24m | D17: 1
C18: Infant Complementary Food- 6 to 12m | D18: 1
C19: Infant Complementary Food- 12 to 24m | D19: 1
C20: Children Powder | D20: 1
C21: Pregnancy Powder | D21: 3
C22: Lactation Powder | D22: 3
... C24: Children Powder | D24: 3
B26: Year 3 | C26: =counta(C27:C50)
C27: Pregnancy Powder- Trimester 1 | D27: 1
C28: Pregnancy Powder- Trimester 2 | D28: 1
C29: Pregnancy Powder- Trimester 3 | D29: 1
C30: Lactation Powder | D30: 1
C31: Infant Formula Powder- 0 to 6m | D31: 1
C32: Infant Formula Powder- 6 to 12m | D32: 1
C33: Infant Formula Powder- 12 to 24m | D33: 1
C34: Infant Complementary Food- 6 to 12m | D34: 1
C35: Infant Complementary Food- 12 to 24m | D35: 1
C36: Children Powder | D36: 1
C37: Pregnancy Powder- Trimester 1 | D37: 2
C38: Pregnancy Powder- Trimester 2 | D38: 2
... C50: Children Powder | D50: 3
B52: Year 4 | C52: =counta(C53:C76)
C53: Pregnancy Powder- Trimester 1 | D53: 1
C54: Pregnancy Powder- Trimester 2 | D54: 1
C55: Pregnancy Powder- Trimester 3 | D55: 1
C56: Lactation Powder | D56: 1
...

Sheet Strategy
H5: Years | I5: 1 | J5: 2 | K5: 3 | L5: 4 | M5: 5
H6: Tiers Targetted | I6: Tier 3 | J6: Tier 1 & 3 | K6: All Tiers | L6: All Tiers | M6: All Tiers
H7: Investor Capital Deployed (in Cr) | I7: 22 | J7: 60 | K7: 220 | L7: 0 | M7: 0
H8: Products (SKUs) | I8: ='Product Line'!C4 | J8: ='Product Line'!C10 | K8: ='Product Line'!C26 | L8: =K8 | M8: =L8
H9: Manufacturing | I9: Contract Manufacturing | J9: In-house & Third Party Manufacturing | K9: In-house & Third Party Manufacturing | L9: In-house & Third Party Manufacturing | M9: In-house & Third Party Manufacturing
H10: Plants Set up | I10: ='In-house (2-5yrs)'!C3 | J10: ='In-house (2-5yrs)'!C4 | K10: ='In-house (2-5yrs)'!C5 | L10: ='In-house (2-5yrs)'!C6 | M10: ='In-house (2-5yrs)'!C7
H11: Total Plants | I11: =I10 | J11: =J10+I11 | K11: =K10+J11 | L11: =L10+K11 | M11: =M10+L11

Sheet P&L
G2: Rs. in cr
B3: YEARS | C3: 1 | D3: 2 | E3: 3 | F3: 4 | G3: 5
B5: REVENUE
B6: Revenue from Operation | C6: ='Contract (1 yr)'!E27 | D6: ='In-house (2-5yrs)'!F4+'Third Party (2-5yrs)'!R4 | E6: ='In-house (2-5yrs)'!F5+'Third Party (2-5yrs)'!R5 | F6: ='In-house (2-5yrs)'!F6+'Third Party (2-5yrs)'!R6 | G6: ='In-house (2-5yrs)'!F7+'Third Party (2-5yrs)'!R7
B7: Pregnancy Powder- Trimester 1- Tier 1 | D7: =('In-house (2-5yrs)'!$C$20/3)/10^7 | E7: =('In-house (2-5yrs)'!$C$21/10^7)/3 | F7: =('In-house (2-5yrs)'!$C$22/10^7)/3 | G7: ='In-house (2-5yrs)'!$C$23/10^7/3
B8: Pregnancy Powder- Trimester 2- Tier 1 | D8: =('In-house (2-5yrs)'!$C$20/3)/10^7 | E8: =('In-house (2-5yrs)'!$C$21/10^7)/3 | F8: =('In-house (2-5yrs)'!$C$22/10^7)/3 | G8: ='In-house (2-5yrs)'!$C$23/10^7/3
B9: Pregnancy Powder- Trimester 3- Tier 1 | D9: =('In-house (2-5yrs)'!$C$20/3)/10^7 | E9: =('In-house (2-5yrs)'!$C$21/10^7)/3 | F9: =('In-house (2-5yrs)'!$C$22/10^7)/3 | G9: ='In-house (2-5yrs)'!$C$23/10^7/3
B10: Lactation Powder- Tier 1 | D10: ='In-house (2-5yrs)'!F20/10^7 | E10: ='In-house (2-5yrs)'!F21/10^7 | F10: ='In-house (2-5yrs)'!F22/10^7 | G10: ='In-house (2-5yrs)'!F23/10^7
B11: Infant Formula Powder- 0 to 6m- Tier 1 | D11: =('In-house (2-5yrs)'!$D$97*'In-house (2-5yrs)'!$I$12)/10^7/5 | E11: =('In-house (2-5yrs)'!$I$21/10^7)/5 | F11: =('In-house (2-5yrs)'!$I$22/10^7)/5 | G11: ='In-house (2-5yrs)'!$I$23/10^7/5
B12: Infant Formula Powder- 6 to 12m- Tier 1 | D12: =('In-house (2-5yrs)'!$D$97*'In-house (2-5yrs)'!$I$12)/10^7/5 | E12: =('In-house (2-5yrs)'!$I$21/10^7)/5 | F12: =('In-house (2-5yrs)'!$I$22/10^7)/5 | G12: ='In-house (2-5yrs)'!$I$23/10^7/5
B13: Infant Formula Powder- 12 to 24m- Tier 1 | D13: =('In-house (2-5yrs)'!$D$97*'In-house (2-5yrs)'!$I$12)/10^7/5 | E13: =('In-house (2-5yrs)'!$I$21/10^7)/5 | F13: =('In-house (2-5yrs)'!$I$22/10^7)/5 | G13: ='In-house (2-5yrs)'!$I$23/10^7/5
B14: Infant Complementary Food- 6 to 12m- Tier 1 | D14: =('In-house (2-5yrs)'!$D$97*'In-house (2-5yrs)'!$I$12)/10^7/5 | E14: =('In-house (2-5yrs)'!$I$21/10^7)/5 | F14: =('In-house (2-5yrs)'!$I$22/10^7)/5 | G14: ='In-house (2-5yrs)'!$I$23/10^7/5
B15: Infant Complementary Food- 12 to 24m- Tier 1 | D15: =('In-house (2-5yrs)'!$D$97*'In-house (2-5yrs)'!$I$12)/10^7/5 | E15: =('In-house (2-5yrs)'!$I$21/10^7)/5 | F15: =('In-house (2-5yrs)'!$I$22/10^7)/5 | G15: ='In-house (2-5yrs)'!$I$23/10^7/5
B16: Children Powder- Tier 1 | D16: =('In-house (2-5yrs)'!L12*'In-house (2-5yrs)'!D100)/10^7 | E16: ='In-house (2-5yrs)'!L21/10^7 | F16: ='In-house (2-5yrs)'!L22/10^7 | G16: ='In-house (2-5yrs)'!L23/10^7
B17: Pregnancy Powder- Trimester 1- Tier 2 | E17: =('In-house (2-5yrs)'!$D$21/10^7)/3 | F17: ='In-house (2-5yrs)'!$D$22/10^7/3 | G17: ='In-house (2-5yrs)'!$D$23/10^7/3
B18: Pregnancy Powder- Trimester 2- Tier 2 | E18: =('In-house (2-5yrs)'!$D$21/10^7)/3 | F18: ='In-house (2-5yrs)'!$D$22/10^7/3 | G18: ='In-house (2-5yrs)'!$D$23/10^7/3
B19: Pregnancy Powder- Trimester 3- Tier 2 | E19: =('In-house (2-5yrs)'!$D$21/10^7)/3 | F19: ='In-house (2-5yrs)'!$D$22/10^7/3 | G19: ='In-house (2-5yrs)'!$D$23/10^7/3
B20: Lactation Powder- Tier 2 | E20: ='In-house (2-5yrs)'!G21/10^7 | F20: ='In-house (2-5yrs)'!G22/10^7 | G20: ='In-house (2-5yrs)'!G23/10^7
B21: Infant Formula Powder- 0 to 6m- Tier 2 | E21: =('In-house (2-5yrs)'!$J$21/10^7)/5 | F21: ='In-house (2-5yrs)'!$J$22/10^7/5 | G21: ='In-house (2-5yrs)'!$J$23/10^7/5
B22: Infant Formula Powder- 6 to 12m- Tier 2 | E22: =('In-house (2-5yrs)'!$J$21/10^7)/5 | F22: ='In-house (2-5yrs)'!$J$22/10^7/5 | G22: ='In-house (2-5yrs)'!$J$23/10^7/5
B23: Infant Formula Powder- 12 to 24m- Tier 2 | E23: =('In-house (2-5yrs)'!$J$21/10^7)/5 | F23: ='In-house (2-5yrs)'!$J$22/10^7/5 | G23: ='In-house (2-5yrs)'!$J$23/10^7/5
B24: Infant Complementary Food- 6 to 12m- Tier 2 | E24: =('In-house (2-5yrs)'!$J$21/10^7)/5 | F24: ='In-house (2-5yrs)'!$J$22/10^7/5 | G24: ='In-house (2-5yrs)'!$J$23/10^7/5
B25: Infant Complementary Food- 12 to 24m- Tier 2 | E25: =('In-house (2-5yrs)'!$J$21/10^7)/5 | F25: ='In-house (2-5yrs)'!$J$22/10^7/5 | G25: ='In-house (2-5yrs)'!$J$23/10^7/5
B26: Children Powder- Tier 2 | E26: ='In-house (2-5yrs)'!M21/10^7 | F26: ='In-house (2-5yrs)'!M22/10^7 | G26: ='In-house (2-5yrs)'!M23/10^7
B27: Pregnancy Powder- Tier 3 | C27: ='Contract (1 yr)'!E25 | D27: =('In-house (2-5yrs)'!E12*'In-house (2-5yrs)'!D93)/10^7 | E27: ='In-house (2-5yrs)'!E21/10^7 | F27: ='In-house (2-5yrs)'!E22/10^7 | G27: ='In-house (2-5yrs)'!E23/10^7
B28: Lactation Powder- Tier 3 | C28: ='Contract (1 yr)'!E26 | D28: =('In-house (2-5yrs)'!D96*'In-house (2-5yrs)'!H12)/10^7 | E28: ='In-house (2-5yrs)'!H21/10^7 | F28: ='In-house (2-5yrs)'!H22/10^7 | G28: ='In-house (2-5yrs)'!H23/10^7
B29: Infant Powder- Tier 3 | C29: ='Contract (1 yr)'!E23 | D29: =('In-house (2-5yrs)'!K12*'In-house (2-5yrs)'!D99)/10^7 | E29: ='In-house (2-5yrs)'!K21/10^7 | F29: ='In-house (2-5yrs)'!K22/10^7 | G29: ='In-house (2-5yrs)'!K23/10^7
B30: Children Powder- Tier 3 | C30: ='Contract (1 yr)'!E24 | D30: =('In-house (2-5yrs)'!D102*'In-house (2-5yrs)'!N12)/10^7 | E30: ='In-house (2-5yrs)'!N21/10^7 | F30: ='In-house (2-5yrs)'!N22/10^7 | G30: ='In-house (2-5yrs)'!N23/10^7
B31: Contract Manufacturing | D31: ='Third Party (2-5yrs)'!R4 | E31: ='Third Party (2-5yrs)'!R5 | F31: ='Third Party (2-5yrs)'!R6 | G31: ='Third Party (2-5yrs)'!R7
B32: Other income | C32: ='Project Financing'!U14 | D32: ='Project Financing'!U15 | E32: ='Project Financing'!U16 | F32: ='Project Financing'!U17 | G32: ='Project Financing'!U18
B33: Total Revenue | C33: =C6+C32 | D33: =D6+D32 | E33: =E6+E32 | F33: =F6+F32 | G33: =G6+G32
B34: Revenue Growth % | D34: =(D33-C33)/C33 | E34: =(E33-D33)/D33 | F34: =(F33-E33)/E33 | G34: =(G33-F33)/F33
B36: COGS | C36: ='Contract (1 yr)'!F27 | D36: ='In-house (2-5yrs)'!G4 | E36: ='In-house (2-5yrs)'!G5 | F36: ='In-house (2-5yrs)'!G6 | G36: ='In-house (2-5yrs)'!G7
B37: Gross Profit Margin % | C37: =C36/C33 | D37: =D36/D33 | E37: =E36/E33 | F37: =F36/F33 | G37: =G36/G33
B39: INDIRECT EXPENSES
B40: Marketing & Advertising | C40: =sum('Indirect Expenses'!C56:E56) | D40: =sum('Indirect Expenses'!F56:H56) | E40: =sum('Indirect Expenses'!I56:K56) | F40: =sum('Indirect Expenses'!L56:N56) | G40: =sum('Indirect Expenses'!O56:Q56) | H40: * Includes Consumer digital ads, Influencer & KOL marketing, Sampling & trial programs, GTM marketing, Branding, Events, etc
B41: Tier 1 | C41: ='Indirect Expenses'!C56 | D41: ='Indirect Expenses'!F56 | E41: ='Indirect Expenses'!I56 | F41: ='Indirect Expenses'!L56 | G41: ='Indirect Expenses'!O56
B42: Tier 2 | C42: ='Indirect Expenses'!D56 | D42: ='Indirect Expenses'!G56 | E42: ='Indirect Expenses'!J56 | F42: ='Indirect Expenses'!M56 | G42: ='Indirect Expenses'!P56
B43: Tier 3 | C43: ='Indirect Expenses'!E56 | D43: ='Indirect Expenses'!H56 | E43: ='Indirect Expenses'!K56 | F43: ='Indirect Expenses'!N56 | G43: ='Indirect Expenses'!Q56
B44: HCP Detailing & Medical Engagement | C44: =sum('Indirect Expenses'!C57:E57) | D44: =sum('Indirect Expenses'!F57:H57) | E44: =sum('Indirect Expenses'!I57:K57) | F44: =sum('Indirect Expenses'!L57:N57) | G44: =sum('Indirect Expenses'!O57:Q57) | H44: * OBGYN, Gynecologist, Pediatrician detailing, Hospital & Nursing home tie-ups, Lactation Consultant & Dietitian programs, Medical conference sponsorships
...

Sheet Competitor Brands
B2: Expense Head | C2: Remarks | D2: HealthKart | E2: Kapiva | F2: OZiva | G2: Wellbeing Nutrition | H2: Early Stage Guide
B4: Marketing & brand
B5: Advertising & Promotions | C5: Digital, influencer, trade mktg | D5: 0.2 | E5: 0.55 | F5: 0.47 | G5: ~38% | H5: 30 – 50%
B6: Brand building & design | C6: Identity, packaging, PR | D6: ~3% | E6: ~5% | F6: ~4% | G6: ~5% | H6: 5 – 10%
B7: Doctor detailing & KOL | C7: Esp. critical for pregnancy/infant | D7: N/A | E7: N/A | F7: N/A | G7: N/A | H7: 3 – 6%
B9: Human resources
B10: Employee benefits | C10: Salaries, PF, ESOP | D10: 0.088 | E10: 0.17 | F10: 0.089 | G10: ~15% | H10: 15 – 25%
B12: Sales & distribution
B13: Channel commissions | C13: Amazon, Flipkart, 1mg, pharmacy | D13: 0.062 | E13: ~8% | F13: ~10% | G13: ~10% | H13: 8 – 12%
B14: Logistics & fulfilment | C14: Freight, 3PL, returns | D14: ~4% | E14: ~6% | F14: ~6% | G14: ~7% | H14: 5 – 8%
B16: Overheads & compliance
B17: Legal, regulatory & FSSAI | D17: ~1% | E17: ~2% | F17: ~2% | G17: ~2% | H17: 2 – 4%
B18: IT, SaaS & tech infra | D18: ~1% | E18: ~2% | F18: ~2% | G18: ~2% | H18: 2 – 4%
B19: Rent, utilities & admin | D19: ~2% | E19: ~3% | F19: ~3% | G19: ~4% | H19: 3 – 6%
B21: R&D & product
B22: R&D, testing & FSSAI dossiers | C22: 1.5-2x higher for infant formula | D22: ~1% | E22: ~1% | F22: ~3% | G22: ~4% | H22: 2 – 5%
B24: Profitability summary
B25: Gross margin | D25: ~51% | E25: ~72% | F25: ~73% | G25: ~70% | H25: 45 – 65%
B26: EBITDA margin | D26: =+6% | E26: -0.21 | F26: -0.012 | G26: ~-5% | H26: -30 to -50%
B27: ₹ spent to earn ₹1 | D27: ₹0.97 | E27: ₹1.22 | F27: ₹1.04 | G27: ~₹1.10 | H27: ₹1.40–1.80

Sheet Revenue Breakup
C2: 1 | E2: 2 | G2: 3 | I2: 4 | K2: 5
B3: Revenue from Operation | C3: ='P&L'!C6 | D3: =C3/$C$3 | E3: ='P&L'!D6 | F3: =E3/$E$3 | G3: ='P&L'!E6 | H3: =G3/$G$3 | I3: ='P&L'!F6 | J3: =I3/$I$3 | K3: ='P&L'!G6 | L3: =K3/$K$3
B4: Pregnancy Powder- Trimester 1- Tier 1 | C4: ='P&L'!C7 | D4: =C4/$C$3 | E4: ='P&L'!D7 | F4: =E4/$E$3 | G4: ='P&L'!E7 | H4: =G4/$G$3 | I4: ='P&L'!F7 | J4: =I4/$I$3 | K4: ='P&L'!G7 | L4: =K4/$K$3
B5: Pregnancy Powder- Trimester 2- Tier 1 | C5: ='P&L'!C8 | D5: =C5/$C$3 | E5: ='P&L'!D8 | F5: =E5/$E$3 | G5: ='P&L'!E8 | H5: =G5/$G$3 | I5: ='P&L'!F8 | J5: =I5/$I$3 | K5: ='P&L'!G8 | L5: =K5/$K$3
B6: Pregnancy Powder- Trimester 3- Tier 1 | C6: ='P&L'!C9 | D6: =C6/$C$3 | E6: ='P&L'!D9 | F6: =E6/$E$3 | G6: ='P&L'!E9 | H6: =G6/$G$3 | I6: ='P&L'!F9 | J6: =I6/$I$3 | K6: ='P&L'!G9 | L6: =K6/$K$3
B7: Lactation Powder- Tier 1 | C7: ='P&L'!C10 | D7: =C7/$C$3 | E7: ='P&L'!D10 | F7: =E7/$E$3 | G7: ='P&L'!E10 | H7: =G7/$G$3 | I7: ='P&L'!F10 | J7: =I7/$I$3 | K7: ='P&L'!G10 | L7: =K7/$K$3
B8: Infant Formula Powder- 0 to 6m- Tier 1 | C8: ='P&L'!C11 | D8: =C8/$C$3 | E8: ='P&L'!D11 | F8: =E8/$E$3 | G8: ='P&L'!E11 | H8: =G8/$G$3 | I8: ='P&L'!F11 | J8: =I8/$I$3 | K8: ='P&L'!G11 | L8: =K8/$K$3
B9: Infant Formula Powder- 6 to 12m- Tier 1 | C9: ='P&L'!C12 | D9: =C9/$C$3 | E9: ='P&L'!D12 | F9: =E9/$E$3 | G9: ='P&L'!E12 | H9: =G9/$G$3 | I9: ='P&L'!F12 | J9: =I9/$I$3 | K9: ='P&L'!G12 | L9: =K9/$K$3
B10: Infant Formula Powder- 12 to 24m- Tier 1 | C10: ='P&L'!C13 | D10: =C10/$C$3 | E10: ='P&L'!D13 | F10: =E10/$E$3 | G10: ='P&L'!E13 | H10: =G10/$G$3 | I10: ='P&L'!F13 | J10: =I10/$I$3 | K10: ='P&L'!G13 | L10: =K10/$K$3
B11: Infant Complementary Food- 6 to 12m- Tier 1 | C11: ='P&L'!C14 | D11: =C11/$C$3 | E11: ='P&L'!D14 | F11: =E11/$E$3 | G11: ='P&L'!E14 | H11: =G11/$G$3 | I11: ='P&L'!F14 | J11: =I11/$I$3 | K11: ='P&L'!G14 | L11: =K11/$K$3
B12: Infant Complementary Food- 12 to 24m- Tier 1 | C12: ='P&L'!C15 | D12: =C12/$C$3 | E12: ='P&L'!D15 | F12: =E12/$E$3 | G12: ='P&L'!E15 | H12: =G12/$G$3 | I12: ='P&L'!F15 | J12: =I12/$I$3 | K12: ='P&L'!G15 | L12: =K12/$K$3
B13: Children Powder- Tier 1 | C13: ='P&L'!C16 | D13: =C13/$C$3 | E13: ='P&L'!D16 | F13: =E13/$E$3 | G13: ='P&L'!E16 | H13: =G13/$G$3 | I13: ='P&L'!F16 | J13: =I13/$I$3 | K13: ='P&L'!G16 | L13: =K13/$K$3
B14: Pregnancy Powder- Trimester 1- Tier 2 | C14: ='P&L'!C17 | D14: =C14/$C$3 | E14: ='P&L'!D17 | F14: =E14/$E$3 | G14: ='P&L'!E17 | H14: =G14/$G$3 | I14: ='P&L'!F17 | J14: =I14/$I$3 | K14: ='P&L'!G17 | L14: =K14/$K$3
... B28: Contract Manufacturing | C28: ='P&L'!C31 | D28: =C28/$C$3 | E28: ='P&L'!D31 | F28: =E28/$E$3 | G28: ='P&L'!E31 | H28: =G28/$G$3 | I28: ='P&L'!F31 | J28: =I28/$I$3 | K28: ='P&L'!G31 | L28: =K28/$K$3
C30: 1 | E30: 2 | G30: 3 | I30: 4 | K30: 5
B31: Tier 1 | C31: =sum(C4:C13) | D31: =sum(D4:D13) | E31: =sum(E4:E13) | F31: =sum(F4:F13) | G31: =sum(G4:G13) | H31: =sum(H4:H13) | I31: =sum(I4:I13) | J31: =sum(J4:J13) | ... L31: =sum(L4:L13)
B32: Tier 2 | C32: =sum(C14:C23) | D32: =sum(D14:D23) | E32: =sum(E14:E23) | F32: =sum(F14:F23) | G32: =sum(G14:G23) | H32: =sum(H14:H23) | I32: =sum(I14:I23) | J32: =sum(J14:J23) | ... L32: =sum(L14:L23)
B33: Tier 3 | C33: =sum(C24:C27) | D33: =sum(D24:D27) | E33: =sum(E24:E27) | F33: =sum(F24:F27) | G33: =sum(G24:G27) | H33: =sum(H24:H27) | I33: =sum(I24:I27) | J33: =sum(J24:J27) | ... L33: =sum(L24:L27)
C35: 1 | D35: 2 | E35: 3 | F35: 4 | G35: 5
B36: Pregnancy Powder | C36: =sum($D$4:$D$6,$D$14:$D$16,$D$24) | D36: =sum(F4:F6,F14:F16,F24) | E36: =sum(H4:H6,H14:H16,H24) | F36: =sum(J4:J6,J14:J16,J24) | G36: =sum(L4:L6,L14:L16,L24)
B37: Lactation Powder | C37: =sum($D$7,$D$17,$D$25) | D37: =sum(F7,F17,F25) | E37: =sum(H7,H17,H25) | F37: =sum(J7,J17,J25) | G37: =sum(L7,L17,L25)
B38: Infant Powder | C38: =sum($D$8:$D$12,$D$18:$D$22,$D$26) | D38: =sum(F8:F12,F18:F22,F26) | E38: =sum(H8:H12,H18:H22,H26) | F38: =sum(J8:J12,J18:J22,J26) | G38: =sum(L8:L12,L18:L22,L26)
B39: Children Powder | C39: =$D$13+$D$23+$D$27 | D39: =F13+F23+F27 | E39: =H13+H23+H27 | F39: =J13+J23+J27 | G39: =L13+L23+L27
B40: Total | C40: =sum(C36:C39) | D40: =sum(D36:D39) | E40: =sum(E36:E39) | F40: =sum(F36:F39) | G40: =sum(G36:G39)
B41: Average | C41: =average(C36:C39) | D41: =average(D36:D39) | E41: =average(E36:E39) | F41: =average(F36:F39) | G41: =average(G36:G39)
C43: 1 | D43: 2 | E43: 3 | F43: 4 | G43: 5
B44: Pregnancy Powder | C44: =VALUE(SUBSTITUTE(C36, "%", "")) | D44: =VALUE(SUBSTITUTE(D36, "%", "")) | E44: =VALUE(SUBSTITUTE(E36, "%", "")) | F44: =VALUE(SUBSTITUTE(F36, "%", "")) | G44: =VALUE(SUBSTITUTE(G36, "%", ""))
B45: Lactation Powder | C45: =VALUE(SUBSTITUTE(C37, "%", "")) | D45: =VALUE(SUBSTITUTE(D37, "%", "")) | E45: =VALUE(SUBSTITUTE(E37, "%", "")) | F45: =VALUE(SUBSTITUTE(F37, "%", "")) | G45: =VALUE(SUBSTITUTE(G37, "%", ""))
B46: Infant Powder | C46: =VALUE(SUBSTITUTE(C38, "%", "")) | D46: =VALUE(SUBSTITUTE(D38, "%", "")) | E46: =VALUE(SUBSTITUTE(E38, "%", "")) | F46: =VALUE(SUBSTITUTE(F38, "%", "")) | G46: =VALUE(SUBSTITUTE(G38, "%", ""))
B47: Children Powder | C47: =VALUE(SUBSTITUTE(C39, "%", "")) | D47: =VALUE(SUBSTITUTE(D39, "%", "")) | E47: =VALUE(SUBSTITUTE(E39, "%", "")) | F47: =VALUE(SUBSTITUTE(F39, "%", "")) | G47: =VALUE(SUBSTITUTE(G39, "%", ""))
C48: =sum(C44:C47) | D48: =sum(D44:D47) | E48: =sum(E44:E47) | F48: =sum(F44:F47) | G48: =sum(G44:G47)

Sheet Indirect Expenses
B2: INDIRECT EXPENSE % BREAKUP TIER WISE & PRODUCT WISE
B3: Cost Head | C3: Remark | D3: Year 1 | G3: Year 2 | J3: Year 3 | M3: Year 4 | P3: Year 5
D4: Tier 1 (Metro) | E4: Tier 2 (Mid Cities) | F4: Tier 3 (Small Towns) | G4: Tier 1 (Metro) | H4: Tier 2 (Mid Cities) | I4: Tier 3 (Small Towns) | J4: Tier 1 (Metro) | K4: Tier 2 (Mid Cities) | L4: Tier 3 (Small Towns) | M4: Tier 1 (Metro) | N4: Tier 2 (Mid Cities) | O4: Tier 3 (Small Towns) | P4: Tier 1 (Metro) | Q4: Tier 2 (Mid Cities) | R4: Tier 3 (Small Towns)
B5: Marketing & Advertising (in %) | C5: * IMS Act prohibits infant formula consumer ads. Tier 1 budget shifts entirely to HCP detailing. 3 brand budgets from Y3. | D5: =VALUE(SUBSTITUTE('IE Biffurcation'!N13, "%", "")) | E5: =VALUE(SUBSTITUTE('IE Biffurcation'!I13, "%", "")) | F5: =VALUE(SUBSTITUTE('IE Biffurcation'!D13, "%", "")) | G5: =VALUE(SUBSTITUTE('IE Biffurcation'!O13, "%", "")) | H5: =VALUE(SUBSTITUTE('IE Biffurcation'!J13, "%", "")) | I5: =VALUE(SUBSTITUTE('IE Biffurcation'!E13, "%", "")) | J5: =VALUE(SUBSTITUTE('IE Biffurcation'!P13, "%", "")) | K5: =VALUE(SUBSTITUTE('IE Biffurcation'!K13, "%", "")) | L5: =VALUE(SUBSTITUTE('IE Biffurcation'!F13, "%", "")) | M5: =VALUE(SUBSTITUTE('IE Biffurcation'!Q13, "%", "")) | N5: =VALUE(SUBSTITUTE('IE Biffurcation'!L13, "%", "")) | O5: =VALUE(SUBSTITUTE('IE Biffurcation'!G13, "%", "")) | P5: =VALUE(SUBSTITUTE('IE Biffurcation'!R13, "%", "")) | Q5: =VALUE(SUBSTITUTE('IE Biffurcation'!M13, "%", "")) | R5: =VALUE(SUBSTITUTE('IE Biffurcation'!H13, "%", ""))
B6: Pregnancy Powder | D6: =D5 | E6: =E5 | F6: =$F$5*'Revenue Breakup'!C36 | G6: =$G$5*('Revenue Breakup'!D36/'Revenue Breakup'!$D$40) | H6: =H5 | I6: =$I$5*('Revenue Breakup'!D36/'Revenue Breakup'!$D$40) | J6: =$J$5*('Revenue Breakup'!E36/'Revenue Breakup'!$E$40) | K6: =$K$5*('Revenue Breakup'!E36/'Revenue Breakup'!$E$40) | L6: =$L$5*('Revenue Breakup'!E36/'Revenue Breakup'!$E$40) | M6: =$M$5*('Revenue Breakup'!F36/'Revenue Breakup'!$F$40) | N6: =$N$5*('Revenue Breakup'!F36/'Revenue Breakup'!$F$40) | O6: =$O$5*('Revenue Breakup'!F36/'Revenue Breakup'!$F$40) | P6: =$P$5*('Revenue Breakup'!G36/'Revenue Breakup'!$G$40) | Q6: =$Q$5*('Revenue Breakup'!G36/'Revenue Breakup'!$G$40) | R6: =$R$5*('Revenue Breakup'!G36/'Revenue Breakup'!$G$40)
B7: Lactation Powder | D7: =D6 | E7: =E6 | F7: =$F$5*'Revenue Breakup'!C37 | G7: =$G$5*('Revenue Breakup'!D37/'Revenue Breakup'!$D$40) | H7: =H6 | I7: =$I$5*('Revenue Breakup'!D37/'Revenue Breakup'!$D$40) | J7: =$J$5*('Revenue Breakup'!E37/'Revenue Breakup'!$E$40) | K7: =$K$5*('Revenue Breakup'!E37/'Revenue Breakup'!$E$40) | L7: =$L$5*('Revenue Breakup'!E37/'Revenue Breakup'!$E$40) | M7: =$M$5*('Revenue Breakup'!F37/'Revenue Breakup'!$F$40) | N7: =$N$5*('Revenue Breakup'!F37/'Revenue Breakup'!$F$40) | O7: =$O$5*('Revenue Breakup'!F37/'Revenue Breakup'!$F$40) | P7: =$P$5*('Revenue Breakup'!G37/'Revenue Breakup'!$G$40) | Q7: =$Q$5*('Revenue Breakup'!G37/'Revenue Breakup'!$G$40) | R7: =$R$5*('Revenue Breakup'!G37/'Revenue Breakup'!$G$40)
B8: Infant Powder | D8: =D7 | E8: =E7 | F8: =$F$5*'Revenue Breakup'!C38 | G8: =$G$5*('Revenue Breakup'!D38/'Revenue Breakup'!$D$40) | H8: =H7 | I8: =$I$5*('Revenue Breakup'!D38/'Revenue Breakup'!$D$40) | J8: =$J$5*('Revenue Breakup'!E38/'Revenue Breakup'!$E$40) | K8: =$K$5*('Revenue Breakup'!E38/'Revenue Breakup'!$E$40) | L8: =$L$5*('Revenue Breakup'!E38/'Revenue Breakup'!$E$40) | M8: =$M$5*('Revenue Breakup'!F38/'Revenue Breakup'!$F$40) | N8: =$N$5*('Revenue Breakup'!F38/'Revenue Breakup'!$F$40) | O8: =$O$5*('Revenue Breakup'!F38/'Revenue Breakup'!$F$40) | P8: =$P$5*('Revenue Breakup'!G38/'Revenue Breakup'!$G$40) | Q8: =$Q$5*('Revenue Breakup'!G38/'Revenue Breakup'!$G$40) | R8: =$R$5*('Revenue Breakup'!G38/'Revenue Breakup'!$G$40)
B9: Children Powder | D9: =D8 | E9: =E8 | F9: =$F$5*'Revenue Breakup'!C39 | G9: =$G$5*('Revenue Breakup'!D39/'Revenue Breakup'!$D$40) | H9: =H8 | I9: =$I$5*('Revenue Breakup'!D39/'Revenue Breakup'!$D$40) | J9: =$J$5*('Revenue Breakup'!E39/'Revenue Breakup'!$E$40) | K9: =$K$5*('Revenue Breakup'!E39/'Revenue Breakup'!$E$40) | L9: =$L$5*('Revenue Breakup'!E39/'Revenue Breakup'!$E$40) | M9: =$M$5*('Revenue Breakup'!F39/'Revenue Breakup'!$F$40) | N9: =$N$5*('Revenue Breakup'!F39/'Revenue Breakup'!$F$40) | O9: =$O$5*('Revenue Breakup'!F39/'Revenue Breakup'!$F$40) | P9: =$P$5*('Revenue Breakup'!G39/'Revenue Breakup'!$G$40) | Q9: =$Q$5*('Revenue Breakup'!G39/'Revenue Breakup'!$G$40) | R9: =$R$5*('Revenue Breakup'!G39/'Revenue Breakup'!$G$40)
B10: HCP Detailing & Medical Engagement (in %) | C10: * OBGYNs, pediatricians, hospitals drive prescription/recommendation. Mandatory for infant formula category growth. | D10: =VALUE(SUBSTITUTE('IE Biffurcation'!N20, "%", "")) | E10: =VALUE(SUBSTITUTE('IE Biffurcation'!I20, "%", "")) | F10: =VALUE(SUBSTITUTE('IE Biffurcation'!D20, "%", "")) | G10: =VALUE(SUBSTITUTE('IE Biffurcation'!O20, "%", "")) | H10: =VALUE(SUBSTITUTE('IE Biffurcation'!J20, "%", "")) | I10: =VALUE(SUBSTITUTE('IE Biffurcation'!E20, "%", "")) | J10: =VALUE(SUBSTITUTE('IE Biffurcation'!P20, "%", "")) | K10: =VALUE(SUBSTITUTE('IE Biffurcation'!K20, "%", "")) | L10: =VALUE(SUBSTITUTE('IE Biffurcation'!F20, "%", "")) | M10: =VALUE(SUBSTITUTE('IE Biffurcation'!Q20, "%", "")) | N10: =VALUE(SUBSTITUTE('IE Biffurcation'!L20, "%", "")) | O10: =VALUE(SUBSTITUTE('IE Biffurcation'!G20, "%", "")) | P10: =VALUE(SUBSTITUTE('IE Biffurcation'!R20, "%", "")) | Q10: =VALUE(SUBSTITUTE('IE Biffurcation'!M20, "%", "")) | R10: =VALUE(SUBSTITUTE('IE Biffurcation'!H20, "%", ""))
B11: Pregnancy Powder | D11: =D10 | E11: =E10 | F11: =$F$10*'Revenue Breakup'!C36 | G11: =$G$10*('Revenue Breakup'!D36/'Revenue Breakup'!$D$40) | H11: =H10 | I11: =$I$10*('Revenue Breakup'!D36/'Revenue Breakup'!$D$40) | J11: =$J$10*('Revenue Breakup'!E36/'Revenue Breakup'!$E$40) | K11: =$K$10*('Revenue Breakup'!E36/'Revenue Breakup'!$E$40) | L11: =$L$10*('Revenue Breakup'!E36/'Revenue Breakup'!$E$40) | M11: =$M$10*('Revenue Breakup'!F36/'Revenue Breakup'!$F$40) | N11: =$N$10*('Revenue Breakup'!F36/'Revenue Breakup'!$F$40) | O11: =$O$10*('Revenue Breakup'!F36/'Revenue Breakup'!$F$40) | P11: =$P$10*('Revenue Breakup'!G36/'Revenue Breakup'!$G$40) | Q11: =$Q$10*('Revenue Breakup'!G36/'Revenue Breakup'!$G$40) | R11: =$R$10*('Revenue Breakup'!G36/'Revenue Breakup'!$G$40)
B12: Lactation Powder | D12: =D11 | E12: =E11 | F12: =$F$10*'Revenue Breakup'!C37 | G12: =$G$10*('Revenue Breakup'!D37/'Revenue Breakup'!$D$40) | H12: =H11 | I12: =$I$10*('Revenue Breakup'!D37/'Revenue Breakup'!$D$40) | J12: =$J$10*('Revenue Breakup'!E37/'Revenue Breakup'!$E$40) | K12: =$K$10*('Revenue Breakup'!E37/'Revenue Breakup'!$E$40) | L12: =$L$10*('Revenue Breakup'!E37/'Revenue Breakup'!$E$40) | M12: =$M$10*('Revenue Breakup'!F37/'Revenue Breakup'!$F$40) | N12: =$N$10*('Revenue Breakup'!F37/'Revenue Breakup'!$F$40) | O12: =$O$10*('Revenue Breakup'!F37/'Revenue Breakup'!$F$40) | P12: =$P$10*('Revenue Breakup'!G37/'Revenue Breakup'!$G$40) | Q12: =$Q$10*('Revenue Breakup'!G37/'Revenue Breakup'!$G$40) | R12: =$R$10*('Revenue Breakup'!G37/'Revenue Breakup'!$G$40)
B13: Infant Powder | D13: =D12 | E13: =E12 | F13: =$F$10*'Revenue Breakup'!C38 | G13: =$G$10*('Revenue Breakup'!D38/'Revenue Breakup'!$D$40) | H13: =H12 | I13: =$I$10*('Revenue Breakup'!D38/'Revenue Breakup'!$D$40) | J13: =$J$10*('Revenue Breakup'!E38/'Revenue Breakup'!$E$40) | K13: =$K$10*('Revenue Breakup'!E38/'Revenue Breakup'!$E$40) | L13: =$L$10*('Revenue Breakup'!E38/'Revenue Breakup'!$E$40) | M13: =$M$10*('Revenue Breakup'!F38/'Revenue Breakup'!$F$40) | N13: =$N$10*('Revenue Breakup'!F38/'Revenue Breakup'!$F$40) | O13: =$O$10*('Revenue Breakup'!F38/'Revenue Breakup'!$F$40) | P13: =$P$10*('Revenue Breakup'!G38/'Revenue Breakup'!$G$40) | Q13: =$Q$10*('Revenue Breakup'!G38/'Revenue Breakup'!$G$40) | R13: =$R$10*('Revenue Breakup'!G38/'Revenue Breakup'!$G$40)
B14: Children Powder | D14: =D13 | E14: =E13 | F14: =$F$10*'Revenue Breakup'!C39 | G14: =$G$10*('Revenue Breakup'!D39/'Revenue Breakup'!$D$40) | H14: =H13 | I14: =$I$10*('Revenue Breakup'!D39/'Revenue Breakup'!$D$40) | J14: =$J$10*('Revenue Breakup'!E39/'Revenue Breakup'!$E$40) | K14: =$K$10*('Revenue Breakup'!E39/'Revenue Breakup'!$E$40) | L14: =$L$10*('Revenue Breakup'!E39/'Revenue Breakup'!$E$40) | M14: =$M$10*('Revenue Breakup'!F39/'Revenue Breakup'!$F$40) | N14: =$N$10*('Revenue Breakup'!F39/'Revenue Breakup'!$F$40) | O14: =$O$10*('Revenue Breakup'!F39/'Revenue Breakup'!$F$40) | P14: =$P$10*('Revenue Breakup'!G39/'Revenue Breakup'!$G$40) | Q14: =$Q$10*('Revenue Breakup'!G39/'Revenue Breakup'!$G$40) | R14: =$R$10*('Revenue Breakup'!G39/'Revenue Breakup'!$G$40)
B15: Distribution & Logistics (in Cr) | C15: * Rs. 9 per box in Year 1 and Year 2. Rs. 8.5 per box Year 3 onwards | D15: =sum(D17:D20) | E15: =sum(E17:E20) | F15: =sum(F17:F20) | G15: =sum(G17:G20) | H15: =sum(H17:H20) | I15: =sum(I17:I20) | J15: =sum(J17:J20) | K15: =sum(K17:K20) | ... R15: =sum(R17:R20)
B16: Cost per Box (in ₹) | D16: 9 | E16: =D16 | F16: =E16 | G16: 9 | H16: =G16 | I16: =H16 | J16: 9 | K16: 9 | L16: 9 | M16: 8 | N16: 8 | O16: 8 | P16: 8 | Q16: 8 | R16: 8
B17: Pregnancy Powder | D17: =D16*'In-house (2-5yrs)'!C11 | E17: =E16*'In-house (2-5yrs)'!D11 | F17: =($F$16*'Contract (1 yr)'!C25)/10^7 | G17: =($G$16*'In-house (2-5yrs)'!C12)/10^7 | H17: =($H$16*'In-house (2-5yrs)'!D12)/10^7 | I17: =($I$16*'In-house (2-5yrs)'!E12)/10^7 | J17: =($J$16*'In-house (2-5yrs)'!C13)/10^7 | K17: =($K$16*'In-house (2-5yrs)'!D13)/10^7 | L17: =($L$16*'In-house (2-5yrs)'!E13)/10^7 | M17: =($M$16*'In-house (2-5yrs)'!C14)/10^7 | N17: =($N$16*'In-house (2-5yrs)'!D14)/10^7 | O17: =($O$16*'In-house (2-5yrs)'!E14)/10^7 | P17: =($P$16*'In-house (2-5yrs)'!C15)/10^7 | Q17: =($Q$16*'In-house (2-5yrs)'!D15)/10^7 | R17: =($R$16*'In-house (2-5yrs)'!E15)/10^7
B18: Lactation Powder | D18: ='In-house (2-5yrs)'!F11*D16 | E18: =E16*'In-house (2-5yrs)'!D11 | F18: =($F$16*'Contract (1 yr)'!C26)/10^7 | G18: =($G$16*'In-house (2-5yrs)'!F12)/10^7 | H18: =($H$16*'In-house (2-5yrs)'!G12)/10^7 | I18: =($I$16*'In-house (2-5yrs)'!H12)/10^7 | J18: =($J$16*'In-house (2-5yrs)'!F13)/10^7 | K18: =($K$16*'In-house (2-5yrs)'!G13)/10^7 | L18: =($L$16*'In-house (2-5yrs)'!H13)/10^7 | M18: =($M$16*'In-house (2-5yrs)'!F14)/10^7 | N18: =($N$16*'In-house (2-5yrs)'!G14)/10^7 | O18: =($O$16*'In-house (2-5yrs)'!H14)/10^7 | P18: =($P$16*'In-house (2-5yrs)'!F15)/10^7 | Q18: =($Q$16*'In-house (2-5yrs)'!G15)/10^7 | R18: =($R$16*'In-house (2-5yrs)'!H15)/10^7
B19: Infant Powder | D19: ='In-house (2-5yrs)'!I11*D16 | E19: ='In-house (2-5yrs)'!J11*E16 | F19: =($F$16*'Contract (1 yr)'!C23)/10^7 | G19: =($G$16*'In-house (2-5yrs)'!I12)/10^7 | H19: =($H$16*'In-house (2-5yrs)'!J12)/10^7 | I19: =($I$16*'In-house (2-5yrs)'!K12)/10^7 | J19: =($J$16*'In-house (2-5yrs)'!I13)/10^7 | K19: =($K$16*'In-house (2-5yrs)'!J13)/10^7 | L19: =($L$16*'In-house (2-5yrs)'!K13)/10^7 | M19: =($M$16*'In-house (2-5yrs)'!I14)/10^7 | N19: =($N$16*'In-house (2-5yrs)'!J14)/10^7 | O19: =($O$16*'In-house (2-5yrs)'!K14)/10^7 | P19: =($P$16*'In-house (2-5yrs)'!I15)/10^7 | Q19: =($Q$16*'In-house (2-5yrs)'!J15)/10^7 | R19: =($R$16*'In-house (2-5yrs)'!K15)/10^7
B20: Children Powder | D20: =D16*'In-house (2-5yrs)'!L11 | E20: =E16*'In-house (2-5yrs)'!M11 | F20: =($F$16*'Contract (1 yr)'!C24)/10^7 | G20: =($G$16*'In-house (2-5yrs)'!L12)/10^7 | H20: =($H$16*'In-house (2-5yrs)'!M12)/10^7 | I20: =($I$16*'In-house (2-5yrs)'!N12)/10^7 | J20: =($J$16*'In-house (2-5yrs)'!L13)/10^7 | K20: =($K$16*'In-house (2-5yrs)'!M13)/10^7 | L20: =($L$16*'In-house (2-5yrs)'!N13)/10^7 | M20: =($M$16*'In-house (2-5yrs)'!L14)/10^7 | N20: =($N$16*'In-house (2-5yrs)'!M14)/10^7 | O20: =($O$16*'In-house (2-5yrs)'!N14)/10^7 | P20: =($P$16*'In-house (2-5yrs)'!L15)/10^7 | Q20: =($Q$16*'In-house (2-5yrs)'!M15)/10^7 | R20: =($R$16*'In-house (2-5yrs)'!N15)/10^7
B21: R&D / Regulatory / Compliance (in %) | C21: * Infant formula under FSS Act strictest category. Each stage/ trimester/ flavour variant = separate FSSAI testing + label approval. | D21: ='IE Biffurcation'!N27 | E21: ='IE Biffurcation'!I27 | F21: =VALUE(SUBSTITUTE('IE Biffurcation'!D27, "%", "")) | G21: =VALUE(SUBSTITUTE('IE Biffurcation'!E27, "%", "")) | H21: ='IE Biffurcation'!J27 | I21: =VALUE(SUBSTITUTE('IE Biffurcation'!O27, "%", "")) | J21: =VALUE(SUBSTITUTE('IE Biffurcation'!F27, "%", "")) | K21: =VALUE(SUBSTITUTE('IE Biffurcation'!K27, "%", "")) | L21: =VALUE(SUBSTITUTE('IE Biffurcation'!P27, "%", "")) | M21: =VALUE(SUBSTITUTE('IE Biffurcation'!G27, "%", "")) | N21: =VALUE(SUBSTITUTE('IE Biffurcation'!L27, "%", "")) | O21: =VALUE(SUBSTITUTE('IE Biffurcation'!Q27, "%", "")) | P21: =VALUE(SUBSTITUTE('IE Biffurcation'!H27, "%", "")) | Q21: =VALUE(SUBSTITUTE('IE Biffurcation'!M27, "%", "")) | R21: =VALUE(SUBSTITUTE('IE Biffurcation'!R27, "%", ""))
B22: Pregnancy Powder | D22: =D21 | E22: =E21 | F22: =$F$21*'Revenue Breakup'!C36 | G22: =$G$21*('Revenue Breakup'!D36/'Revenue Breakup'!$D$40) | H22: =H21 | I22: =$I$21*('Revenue Breakup'!D36/'Revenue Breakup'!$D$40) | J22: =$J$21*('Revenue Breakup'!E36/'Revenue Breakup'!$E$40) | K22: =$K$21*('Revenue Breakup'!E36/'Revenue Breakup'!$E$40) | L22: =$L$21*('Revenue Breakup'!E36/'Revenue Breakup'!$E$40) | M22: =$M$21*('Revenue Breakup'!F36/'Revenue Breakup'!$F$40) | N22: =$N$21*('Revenue Breakup'!F36/'Revenue Breakup'!$F$40) | O22: =$O$21*('Revenue Breakup'!F36/'Revenue Breakup'!$F$40) | P22: =$P$21*('Revenue Breakup'!G36/'Revenue Breakup'!$G$40) | Q22: =$Q$21*('Revenue Breakup'!G36/'Revenue Breakup'!$G$40) | R22: =$R$21*('Revenue Breakup'!G36/'Revenue Breakup'!$G$40)
B23: Lactation Powder | D23: =D22 | E23: =E22 | F23: =$F$21*'Revenue Breakup'!C37 | G23: =$G$21*('Revenue Breakup'!D37/'Revenue Breakup'!$D$40) | H23: =H22 | I23: =$I$21*('Revenue Breakup'!D37/'Revenue Breakup'!$D$40) | J23: =$J$21*('Revenue Breakup'!E37/'Revenue Breakup'!$E$40) | K23: =$K$21*('Revenue Breakup'!E37/'Revenue Breakup'!$E$40) | L23: =$L$21*('Revenue Breakup'!E37/'Revenue Breakup'!$E$40) | M23: =$M$21*('Revenue Breakup'!F37/'Revenue Breakup'!$F$40) | N23: =$N$21*('Revenue Breakup'!F37/'Revenue Breakup'!$F$40) | O23: =$O$21*('Revenue Breakup'!F37/'Revenue Breakup'!$F$40) | P23: =$P$21*('Revenue Breakup'!G37/'Revenue Breakup'!$G$40) | Q23: =$Q$21*('Revenue Breakup'!G37/'Revenue Breakup'!$G$40) | R23: =$R$21*('Revenue Breakup'!G37/'Revenue Breakup'!$G$40)
B24: Infant Powder | D24: =D23 | E24: =E23 | F24: =$F$21*'Revenue Breakup'!C38 | G24: =$G$21*('Revenue Breakup'!D38/'Revenue Breakup'!$D$40) | H24: =H23 | I24: =$I$21*('Revenue Breakup'!D38/'Revenue Breakup'!$D$40) | J24: =$J$21*('Revenue Breakup'!E38/'Revenue Breakup'!$E$40) | K24: =$K$21*('Revenue Breakup'!E38/'Revenue Breakup'!$E$40) | L24: =$L$21*('Revenue Breakup'!E38/'Revenue Breakup'!$E$40) | M24: =$M$21*('Revenue Breakup'!F38/'Revenue Breakup'!$F$40) | N24: =$N$21*('Revenue Breakup'!F38/'Revenue Breakup'!$F$40) | O24: =$O$21*('Revenue Breakup'!F38/'Revenue Breakup'!$F$40) | P24: =$P$21*('Revenue Breakup'!G38/'Revenue Breakup'!$G$40) | Q24: =$Q$21*('Revenue Breakup'!G38/'Revenue Breakup'!$G$40) | R24: =$R$21*('Revenue Breakup'!G38/'Revenue Breakup'!$G$40)
B25: Children Powder | D25: =D24 | E25: =E24 | F25: =$F$21*'Revenue Breakup'!C39 | G25: =$G$21*('Revenue Breakup'!D39/'Revenue Breakup'!$D$40) | H25: =H24 | I25: =$I$21*('Revenue Breakup'!D39/'Revenue Breakup'!$D$40) | J25: =$J$21*('Revenue Breakup'!E39/'Revenue Breakup'!$E$40) | K25: =$K$21*('Revenue Breakup'!E39/'Revenue Breakup'!$E$40) | L25: =$L$21*('Revenue Breakup'!E39/'Revenue Breakup'!$E$40) | M25: =$M$21*('Revenue Breakup'!F39/'Revenue Breakup'!$F$40) | N25: =$N$21*('Revenue Breakup'!F39/'Revenue Breakup'!$F$40) | O25: =$O$21*('Revenue Breakup'!F39/'Revenue Breakup'!$F$40) | P25: =$P$21*('Revenue Breakup'!G39/'Revenue Breakup'!$G$40) | Q25: =$Q$21*('Revenue Breakup'!G39/'Revenue Breakup'!$G$40) | R25: =$R$21*('Revenue Breakup'!G39/'Revenue Breakup'!$G$40)
B26: G&A / Operations Overheads (in %) | D26: ='IE Biffurcation'!N33 | E26: ='IE Biffurcation'!I33 | F26: =VALUE(SUBSTITUTE('IE Biffurcation'!D33, "%", "")) | G26: =VALUE(SUBSTITUTE('IE Biffurcation'!E33, "%", "")) | H26: ='IE Biffurcation'!J33 | I26: =VALUE(SUBSTITUTE('IE Biffurcation'!O33, "%", "")) | J26: =VALUE(SUBSTITUTE('IE Biffurcation'!F33, "%", "")) | K26: =VALUE(SUBSTITUTE('IE Biffurcation'!K33, "%", "")) | L26: =VALUE(SUBSTITUTE('IE Biffurcation'!P33, "%", "")) | M26: =VALUE(SUBSTITUTE('IE Biffurcation'!G33, "%", "")) | N26: =VALUE(SUBSTITUTE('IE Biffurcation'!L33, "%", "")) | O26: =VALUE(SUBSTITUTE('IE Biffurcation'!Q33, "%", "")) | P26: =VALUE(SUBSTITUTE('IE Biffurcation'!H33, "%", "")) | Q26: =VALUE(SUBSTITUTE('IE Biffurcation'!M33, "%", "")) | R26: =VALUE(SUBSTITUTE('IE Biffurcation'!R33, "%", ""))
B27: Pregnancy Powder | D27: =D26 | E27: =E26 | F27: =$F$26*('Revenue Breakup'!C36) | G27: =$G$26*('Revenue Breakup'!D36/'Revenue Breakup'!$D$40) | H27: =H26 | I27: =$I$26*('Revenue Breakup'!D36/'Revenue Breakup'!$D$40) | J27: =$J$26*('Revenue Breakup'!E36/'Revenue Breakup'!$E$40) | K27: =$K$26*('Revenue Breakup'!E36/'Revenue Breakup'!$E$40) | L27: =$K$26*('Revenue Breakup'!E36/'Revenue Breakup'!$E$40) | M27: =$M$26*('Revenue Breakup'!F36/'Revenue Breakup'!$F$40) | N27: =$N$26*('Revenue Breakup'!F36/'Revenue Breakup'!$F$40) | O27: =$O$26*('Revenue Breakup'!F36/'Revenue Breakup'!$F$40) | P27: =$P$26*('Revenue Breakup'!G36/'Revenue Breakup'!$G$40) | Q27: =$Q$26*('Revenue Breakup'!G36/'Revenue Breakup'!$G$40) | R27: =$R$26*('Revenue Breakup'!G36/'Revenue Breakup'!$G$40)
B28: Lactation Powder | D28: =D27 | E28: =E27 | F28: =$F$26*('Revenue Breakup'!C37) | G28: =$G$26*('Revenue Breakup'!D37/'Revenue Breakup'!$D$40) | H28: =H27 | I28: =$I$26*('Revenue Breakup'!D37/'Revenue Breakup'!$D$40) | J28: =$J$26*('Revenue Breakup'!E37/'Revenue Breakup'!$E$40) | K28: =$K$26*('Revenue Breakup'!E37/'Revenue Breakup'!$E$40) | L28: =$K$26*('Revenue Breakup'!E37/'Revenue Breakup'!$E$40) | M28: =$M$26*('Revenue Breakup'!F37/'Revenue Breakup'!$F$40) | N28: =$N$26*('Revenue Breakup'!F37/'Revenue Breakup'!$F$40) | O28: =$O$26*('Revenue Breakup'!F37/'Revenue Breakup'!$F$40) | P28: =$P$26*('Revenue Breakup'!G37/'Revenue Breakup'!$G$40) | Q28: =$Q$26*('Revenue Breakup'!G37/'Revenue Breakup'!$G$40) | R28: =$R$26*('Revenue Breakup'!G37/'Revenue Breakup'!$G$40)
