Workbook
Name Medak: #REF!

Sheet Index
B2: Bill Of Material (BOM)
B3: 1 | C3: Pregnancy Powder
B4: 2 | C4: Lactation Powder
B5: 3 | C5: Infant Formula Milk
B6: 4 | C6: Child Nutrition
B8: Profit & Loss Statement
B10: 22Cr Summary Sheet
B12: Year 1
B13: 1 | C13: 22Cr Capital Raised Working
B14: 2 | C14: Working Capital
B16: Year 2
B17: 1 | C17: 60Cr Capital Raised Working
B18: 2 | C18: Working Capital
B20: Year 3
B21: 1 | C21: Plant works @ 100% Efficiency
B22: 2 | C22: Working Capital

Sheet Infant Complementary BOM
B2: RAW MATERIAL COST
B4: Item No. | C4: Ingredient Name | D4: In Grams | F4: In Rupees
D5: Quantity Per 100 g | E5: Quantity per 400 gm | F5: Rate / Kg | G5: Rate / Gram | H5: Rate Per 400 g
B6: 1 | C6: Milk Solids | D6: 35 | E6: =D6*4 -> 140 | F6: 240 | G6: =F6/1000 -> 0.24 | H6: =E6*G6 -> 33.6
B7: 2 | C7: Maltodextrin | D7: 20 | E7: =D7*4 -> 80 | F7: 50 | G7: =F7/1000 -> 0.05 | H7: =E7*G7 -> 4
B8: 3 | C8: Sprouted Ragi Powder | D8: 13 | E8: =D8*4 -> 52 | F8: 50 | G8: =F8/1000 -> 0.05 | H8: =E8*G8 -> 2.6
B9: 4 | C9: Rice Powder | D9: 10 | E9: =D9*4 -> 40 | F9: 50 | G9: =F9/1000 -> 0.05 | H9: =E9*G9 -> 2
B10: 5 | C10: Apple Powder | D10: 8 | E10: =D10*4 -> 32 | F10: 170 | G10: =F10/1000 -> 0.17 | H10: =E10*G10 -> 5.44
B11: 6 | C11: Enzyme(Alpha Amylase) | D11: 0.5 | E11: =D11*4 -> 2 | F11: 1000 | G11: =F11/1000 -> 1 | H11: =E11*G11 -> 2
B12: 7 | C12: Fructooligosaccharides | D12: 7 | E12: =D12*4 -> 28 | F12: 170 | G12: =F12/1000 -> 0.17 | H12: =E12*G12 -> 4.76
B13: 8 | C13: Mineral premix(Calcium, Phosphorous, Sodium, Potassium, Chloride, Magnesium, Iron, Zinc, Copper, Manganese, Iodine, Selenium) | D13: 1.88 | E13: =D13*4 -> 7.52 | F13: 400 | G13: =F13/1000 -> 0.4 | H13: =E13*G13 -> 3.008
B14: 9 | C14: Vitamin premix(Vitamin A, D, E, K, C, B1, B2, B6, B12, B7,B5, B3) | D14: 0.05 | E14: =D14*4 -> 0.2 | F14: 500 | G14: =F14/1000 -> 0.5 | H14: =E14*G14 -> 0.1
B15: 10 | C15: Jaggery Powder | D15: 5 | E15: =D15*4 -> 20 | F15: 60 | G15: =F15/1000 -> 0.06 | H15: =E15*G15 -> 1.2
B16: RAW MATERIAL TOTAL COST | D16: =SUM(D6:D15) -> 100.43 | E16: =D16*4 -> 401.72 | H16: =SUM(H6:H14) -> 57.508
B18: OTHER COSTS
C20: Packaging | H20: 12
C21: Conversion | H21: 30
F23: TOTAL COST / BOX | H23: =H16+H20+H21 -> 99.508
F25: PRODUCTION COST / BATCH | H25: 20000000
F27: BOXES / BATCH | H27: =H25/H23 -> 200988.87
F29: BOXES / VARIANT | H29: =H27/3 -> 66996.288
F31: AS PER PROJETIONS SHEET
F32: Total Cost (Excl. GST) | H32: 111 | I32: VS | J32: =H23 -> 99.508
F33: GST 18% | H33: 16
F34: Total Cost (Incl. GST) | H34: 127

Sheet Total Production
A1: VALENCIA NUTRACARE LIFESCIENCES (Consumer Validation)
B3: EARLY STAGE FUND | C3: Natal Care | D3: Infant & Child Nutrition | E3: Total
B4: Funding (₹ Cr) | C4: 11 | D4: 11 | E4: =C4+D4 -> 22
B5: Production (₹ Cr) | C5: 8 | D5: 8 | E5: =C5+D5 -> 16 | F5: * 2 cycles of production
B6: Admin & Marketing Exp (₹ Cr) | C6: 3 | D6: 3 | E6: =C6+D6 -> 6
C8: Pregnancy Powder (Garbhika) | D8: Lactation Powder (Matrusneha) | E8: Infant Formula Milk Powder (Poshit) | F8: Child Nutrition Powder
B9: Cost/Box | C9: ='PP BOM'!H25 -> 178.594 | D9: ='LP BOM'!H28 -> 158.835 | E9: ='IFM BOM'!H30 -> 124.1836 | F9: ='CNP BOM'!H24 -> 121.88
B10: Production Cost/Batch | C10: ='PP BOM'!H27 -> 20000000 | D10: ='LP BOM'!H30 -> 20000000 | E10: ='IFM BOM'!H32 -> 20000000 | F10: ='CNP BOM'!H26 -> 20000000
B11: Boxes/Batch | C11: =Round(C10/C9,0) -> 111986 | D11: =Round(D10/D9,0) -> 125917 | E11: =Round(E10/E9,0) -> 161052 | F11: =Round(F10/F9,0) -> 164096
B13: TOTAL BOXES | C13: =C11+D11+E11+F11 -> 563051
B15: AVERAGE BOXES/VARIANT | C15: =average(C11:F11) -> 140762.75
B17: AVERAGE COST/BOX | C17: =average(C9:F9) -> 145.87315
B19: Products | C19: Selling Price (in ₹) | D19: Boxes/Batch | E19: Revenue / Batch (in ₹) | F19: COGS / Batch (in ₹) | G19: Gross Profit/ Batch (in ₹)
B20: Pregnancy Powder | C20: 280 | D20: =C11 -> 111986 | E20: =C20*D20 -> 31356080 | F20: =D20*C9 -> 20000028 | G20: =E20-F20 -> 11356052
B21: Lactation Powder | C21: 286 | D21: =D11 -> 125917 | E21: =C21*D21 -> 36012262 | F21: =D21*D9 -> 20000027 | G21: =E21-F21 -> 16012235
B22: Infant Formula Milk Powder | C22: 242 | D22: =E11 -> 161052 | E22: =C22*E11 -> 38974584 | F22: =D22*E9 -> 20000017 | G22: =E22-F22 -> 18974567
B23: Child Nutrition Powder | C23: 212 | D23: =F11 -> 164096 | E23: =C23*F11 -> 34788352 | F23: =D23*F9 -> 20000020 | G23: =E23-F23 -> 14788332
D24: TOTAL (in ₹) | E24: =SUM(E20:E23) -> 141131278 | F24: =SUM(F20:F23) -> 80000092 | G24: =SUM(G20:G23) -> 61131186
D25: TOTAL (₹ in Cr) | E25: =E24/10^7 -> 14.113128 | F25: =F24/10^7 -> 8.0000092 | G25: =G24/10^7 -> 6.1131186
B28: Amount in ₹ Cr
B29: Gross Profit | C29: =G25 -> 6.1131186
B30: Marketing Expense | C30: =#REF! -> #REF!
B31: EBITDA | C31: =C29-C30 -> #REF!
B33: Remaining Funds | C33: =(E5+E6)/2 -> 11 | D33: * 8cr for Production, 3cr for Marketing Expense
B34: Production Funds for Batch 2 | C34: =C31+(E5/2) -> #REF!
B36: Maketing Funds for Batch 2 | C36: =E6/2 -> 3
B38: TRIO FIT WORKING CAPACITY
C39: 1 day | D39: Working Efficiency | F39: Bulk density | G39: Manufacturing | H39: 1 day
B40: Blender | C40: 500l | D40: 0.7 | E40: =1200 -> 1200 | F40: 0.4 | G40: 400kg/5 hrs | H40: 800kg
B41: Blender 1 | C41: 1500 | D41: 0.7
B42: Blender 2 | C42: =300 -> 300 | D42: 0.7 | G42: 100kg/5hrs | H42: 200kg
C44: PP | D44: LP | E44: IFP | F44: CNP
B45: Kgs to be Manufactured | C45: =C11*0.5 -> 55993 | D45: =D11*0.5 -> 62958.5 | E45: =(E11*400)/1000 -> 64420.8 | F45: =(F11*400)/1000 -> 65638.4 | G45: * 1 batch capacity
B46: Tons to be Manufactured | C46: =C45/1000 -> 55.993 | D46: =D45/1000 -> 62.9585 | E46: =E45/1000 -> 64.4208 | F46: =F45/1000 -> 65.6384
C48: Total Production Capacity | D48: Days | E48: Months (25 days working)
C49: =2*300*1000 -> 600000 | D49: 300 | E49: =D49/25 -> 12
C50: =sum(C45:F45) -> 249010.7 | D50: =(C50*D49)/C49 -> 124.50535 | E50: =D50/25 -> 4.980214
C52: 1 DAY PRODUCTION CAPACITY (Rohan sir's factory)
C53: PP | D53: LP | E53: IFP | F53: CNP
B54: Boxes | C54: =C55*2 -> 795.56559 | D54: =D55*2 -> 894.53353 | E54: =(E55*1000)/400 -> 1430.1724 | F54: =(F55*1000)/400 -> 1457.2037 | G54: =SUM(C54:F54) -> 4577.4752
...

Sheet Year 2
B2: YEAR 2 FUNDING (in Cr) | C2: 60
C4: Pregnancy Powder (Garbhika) | D4: Lactation Powder (Matrusneha) | E4: Infant Formula Milk Powder (Poshit) | F4: Child Nutrition Powder
B5: Cost/Box | C5: ='PP BOM'!H32 -> #REF! | D5: ='LP BOM'!H35 -> #REF! | E5: ='IFM BOM'!H39 -> #REF! | F5: ='CNP BOM'!H31 -> #REF!
B6: Selling Price/Box | C6: ='Total Production'!C20 -> 280 | D6: ='Total Production'!C21 -> 286 | E6: ='Total Production'!C22 -> 242 | F6: ='Total Production'!C23 -> 212
B7: Profit/Box | C7: =C6-C5 -> #REF! | D7: =D6-D5 -> #REF! | E7: =E6-E5 -> #REF! | F7: =F6-F5 -> #REF!
B9: Taking into consideration the following information:
B10: Tons Manufactured / Day | C10: 40 | D10: * 2 tons a day at Rohan Sir's Factory (Natal Care only). Assuming another factory will have 2 tons too
B11: Kgs Manufactured / Day | C11: =C10*1000 -> 40000
B12: Boxes Manufactured / Day | C12: =((C11*1000*0.5)/500)+((C11*1000*0.5)/400) -> 90000
B14: Natal Care Boxes/Day | C14: =((C11*1000*0.5)/500)*C76 -> 0 | D14: * Natal Care Products are 500gms each
B15: Infant & Child Care Boxes/Day | C15: =((C11*1000*0.5)/400)*C76 -> 0 | D15: * Infant and Child Care Products are 400gms each
B17: Working Days/Month | C17: 25
B18: Working Months/Year | C18: 12
B19: Working Days/Year | C19: =C17*C18 -> 300
B21: PRODUCTION
B22: Products | C22: Boxes/Year | D22: Revenue/Year | E22: Revenue (in Cr) | F22: COGS (in Cr) | G22: Gross Profit (in Cr)
B23: Infant Formula Milk | C23: =($C$19*$C$15)/2 -> 0 | D23: =C23*E6 -> 0 | E23: =D23/10^7 -> 0 | F23: =(C23*E5)/10^7 -> #REF! | G23: =E23-F23 -> #REF!
B24: Child Nutrition Powder | C24: =($C$19*$C$15)/2 -> 0 | D24: =C24*F6 -> 0 | E24: =D24/10^7 -> 0 | F24: =(C24*F5)/10^7 -> #REF! | G24: =E24-F24 -> #REF!
B25: Pregnancy Powder | C25: =($C$19*$C$14)/2 -> 0 | D25: =C25*C6 -> 0 | E25: =D25/10^7 -> 0 | F25: =(C25*C5)/10^7 -> #REF! | G25: =E25-F25 -> #REF!
B26: Lactation Powder | C26: =($C$19*$C$14)/2 -> 0 | D26: =C26*D6 -> 0 | E26: =D26/10^7 -> 0 | F26: =(C26*D5)/10^7 -> #REF! | G26: =E26-F26 -> #REF!
C27: =sum(C23:C26) -> 0 | E27: =sum(E23:E26) -> 0 | F27: =sum(F23:F26) -> #REF! | G27: =sum(G23:G26) -> #REF!
B29: WORKING CAPITAL
C30: Year 1 | D30: Year 2 | E30: Fresh Capital Needed
B31: Working Capital (in Cr) | C31: ='Contract (1 yr)'!C30 -> 21.598213 | D31: ='WC (Year 3-5)'!D17/10^7 -> #REF! | E31: =D31-C31 -> #REF!
B32: Pregnancy Powder (in Cr) | C32: ='Contract (1 yr)'!C31 -> 5.7940809 | D32: ='WC (Year 3-5)'!D5/10^7 -> #REF! | E32: =D32-C32 -> #REF!
B33: Lactation Powder (in Cr) | C33: ='Contract (1 yr)'!C32 -> 5.3445637 | D33: ='WC (Year 3-5)'!D8/10^7 -> #REF! | E33: =D33-C33 -> #REF!
B34: Infant Formula Milk (in Cr) | C34: ='Contract (1 yr)'!C33 -> 5.2625385 | D34: ='WC (Year 3-5)'!D11/10^7 -> #REF! | E34: =D34-C34 -> #REF!
B35: Child Nutrition Powder (in Cr) | C35: ='Contract (1 yr)'!C34 -> 5.1970299 | D35: ='WC (Year 3-5)'!D14/10^7 -> #REF! | E35: =D35-C35 -> #REF!
B37: APPLICATION & SOURCES OF FUND
B38: Sources of Fund | C38: =C42 -> #REF!
B39: A. VNL | C39: =C38-C40-C41 -> #REF!
B40: B. Capital Raise | C40: =C2 -> 60
B41: C. Existing Working Capital | C41: =C31 -> 21.598213
B42: Application of Fund | C42: =sum(C43:C45) -> #REF!
B43: A. Production | C43: ='WC (Year 3-5)'!H17/10^7 -> 0
B44: B. Indirect Expense | C44: ='WC (Year 3-5)'!I17/10^7 -> 0
B45: C. Plant CAPEX | C45: =C64 -> #REF!
B47: CAPEX TABLE
B48: Cost of Project | C48: Cost (in Cr)
B49: Land and Plant Building | C49: =IFERROR(__xludf.DUMMYFUNCTION("importrange(""https://docs.google.com/spreadsheets/d/1bEcp3VCHzQgxan8VY9FCqLk1Yk8qAjekoqv5jLH-RCM/edit?gid=3774512#gid=3774512"",""Capex & Depreciation!C12:C26"")"),"#REF!") -> #REF!
...

Sheet Year 3
B2: YEAR 3 FUNDING (in Cr) | C2: 0
C4: Pregnancy Powder (Garbhika) | D4: Lactation Powder (Matrusneha) | E4: Infant Formula Milk Powder (Poshit) | F4: Child Nutrition Powder
B5: Cost/Box | C5: ='PP BOM'!H32 -> #REF! | D5: ='LP BOM'!H35 -> #REF! | E5: ='IFM BOM'!H39 -> #REF! | F5: ='CNP BOM'!H31 -> #REF!
B6: Selling Price/Box | C6: ='Total Production'!C20 -> 280 | D6: ='Total Production'!C21 -> 286 | E6: ='Total Production'!C22 -> 242 | F6: ='Total Production'!C23 -> 212
B7: Profit/Box | C7: =C6-C5 -> #REF! | D7: =D6-D5 -> #REF! | E7: =E6-E5 -> #REF! | F7: =F6-F5 -> #REF!
B9: Taking into consideration the following information:
B10: Tons Manufactured / Day | C10: 40 | D10: * 2 tons a day at Rohan Sir's Factory (Natal Care only). Assuming another factory will have 2 tons too
B11: Kgs Manufactured / Day | C11: =C10*1000 -> 40000
B12: Boxes Manufactured / Day | C12: =((C11*1000*0.5)/500)+((C11*1000*0.5)/400) -> 90000
B14: Natal Care Boxes/Day | C14: =((C11*1000*0.5)/500)*C75 -> 0 | D14: * Natal Care Products are 500gms each
B15: Infant & Child Care Boxes/Day | C15: =((C11*1000*0.5)/400)*C75 -> 0 | D15: * Infant and Child Care Products are 400gms each
B17: Working Days/Month | C17: 25
B18: Working Months/Year | C18: 12
B19: Working Days/Year | C19: =C17*C18 -> 300
B21: PRODUCTION
B22: Products | C22: Boxes/Year | D22: Revenue/Year | E22: Revenue (in Cr) | F22: COGS (in Cr) | G22: Gross Profit (in Cr)
B23: Infant Formula Milk | C23: =($C$19*$C$15)/2 -> 0 | D23: =C23*E6 -> 0 | E23: =D23/10^7 -> 0 | F23: =(C23*E5)/10^7 -> #REF! | G23: =E23-F23 -> #REF!
B24: Child Nutrition Powder | C24: =($C$19*$C$15)/2 -> 0 | D24: =C24*F6 -> 0 | E24: =D24/10^7 -> 0 | F24: =(C24*F5)/10^7 -> #REF! | G24: =E24-F24 -> #REF!
B25: Pregnancy Powder | C25: =($C$19*$C$14)/2 -> 0 | D25: =C25*C6 -> 0 | E25: =D25/10^7 -> 0 | F25: =(C25*C5)/10^7 -> #REF! | G25: =E25-F25 -> #REF!
B26: Lactation Powder | C26: =($C$19*$C$14)/2 -> 0 | D26: =C26*D6 -> 0 | E26: =D26/10^7 -> 0 | F26: =(C26*D5)/10^7 -> #REF! | G26: =E26-F26 -> #REF!
C27: =sum(C23:C26) -> 0 | E27: =sum(E23:E26) -> 0 | F27: =sum(F23:F26) -> #REF! | G27: =sum(G23:G26) -> #REF!
B29: WORKING CAPITAL
C30: Year 3 | D30: Year 2 | E30: Fresh Capital Needed
B31: Working Capital (in Cr) | C31: ='WC (Year 3)'!D9/10^7 -> #REF! | D31: ='Year 2'!D31 -> #REF! | E31: =C31-D31 -> #REF!
B32: Pregnancy Powder (in Cr) | C32: ='WC (Year 3)'!D5/10^7 -> #REF! | D32: ='WC (Year 3-5)'!D5/10^7 -> #REF! | E32: =C32-D32 -> #REF!
B33: Lactation Powder (in Cr) | C33: ='WC (Year 3)'!D6/10^7 -> #REF! | D33: ='WC (Year 3-5)'!D8/10^7 -> #REF! | E33: =C33-D33 -> #REF!
B34: Infant Formula Milk (in Cr) | C34: ='WC (Year 3)'!D7/10^7 -> #REF! | D34: ='WC (Year 3-5)'!D11/10^7 -> #REF! | E34: =C34-D34 -> #REF!
B35: Child Nutrition Powder (in Cr) | C35: ='WC (Year 3)'!D8/10^7 -> #REF! | D35: ='WC (Year 3-5)'!D14/10^7 -> #REF! | E35: =C35-D35 -> #REF!
B37: APPLICATION & SOURCES OF FUND
B38: Sources of Fund | C38: =C42 -> #REF!
B39: A. VNL Retained Earnings | C39: =C38-C40-C41 -> #REF! | D39: * 7.58% of Retained Earnings
B40: B. Capital Raise | C40: =C2 -> 0
B41: C. Existing Working Capital | C41: =D31 -> #REF!
B42: Application of Fund | C42: =sum(C43:C44) -> #REF!
B43: A. Production | C43: ='WC (Year 3)'!H9/10^7 -> #REF!
B44: B. Indirect Expense | C44: ='WC (Year 3)'!I9/10^7 -> 0
B46: CAPEX TABLE
B47: Cost of Project | C47: Cost (in Cr)
B48: Land and Plant Building | C48: =IFERROR(__xludf.DUMMYFUNCTION("importrange(""https://docs.google.com/spreadsheets/d/1bEcp3VCHzQgxan8VY9FCqLk1Yk8qAjekoqv5jLH-RCM/edit?gid=3774512#gid=3774512"",""Capex & Depreciation!C12:C26"")"),"#REF!") -> #REF!
B49: Utilities (Power, Tanks etc.)
...

Sheet WC (Year 3)
B2: TOTAL WORKING CAPITAL | G2: APPLICATION OF FUNDS
C4: Revenue | D4: Initial Working Capital | E4: W.C.Rotation | H4: Production | I4: Indirect Expense
B5: PP | C5: =D35 -> 0 | D5: =D36 -> #REF! | E5: =C5/D5 -> #REF! | G5: PP | H5: =(D13*D14)*2.5 -> #REF! | I5: =D16*2.5 -> 0
B6: LP | C6: =D64 -> 0 | D6: =D65 -> #REF! | E6: =C6/D6 -> #REF! | G6: LP | H6: =(D42*D43)*2.5 -> #REF! | I6: =D45*2.5 -> 0
B7: IFP | C7: =D93 -> 0 | D7: =D94 -> #REF! | E7: =C7/D7 -> #REF! | G7: IFP | H7: =(D71*D72)*2.5 -> #REF! | I7: =D74*2.5 -> 0
B8: CNP | C8: =D122 -> 0 | D8: =D123 -> #REF! | E8: =C8/D8 -> #REF! | G8: CNP | H8: =(D100*D101)*2.5 -> #REF! | I8: =D103*2.5 -> 0
D9: =sum(D5:D8) -> #REF! | H9: =sum(H5:H8) -> #REF! | I9: =sum(I5:I8) -> 0
H10: =H9+I9 -> #REF!
B11: PREGNANCY POWDER
B13: Monthly Boxes Produced (in Units) | D13: ='Year 3'!C25/12 -> 0
B14: Cost/Box (in ₹) | D14: ='Year 2'!C5 -> #REF!
B15: Revenue/Box (in ₹) | D15: ='Year 2'!C6 -> 280
B16: Monthly Indirect Expense (in ₹) | D16: =('Year 2'!$E$88/12)/4 -> 0
G17: * The working capital that we are investing in the first month is derived from the cash outflow that is required in the first month
B18: Month | C18: Cash Outflow | D18: Cash Inflow | E18: Difference (CO-CI) | G18: Opening W.C. | H18: Net Cash Flow | I18: Closing W.C.
B19: April | C19: =($D$13*$D$14)+$D$16 -> #REF! | D19: =$D$13*$D$15 -> 0 | E19: =D19-C19 -> #REF! | G19: =C19+D33 -> #REF! | H19: =E19 -> #REF! | I19: =G19+H19 -> #REF!
B20: May | C20: =($D$13*$D$14)+$D$16 -> #REF! | D20: =$D$13*$D$15 -> 0 | E20: =D20-C20 -> #REF! | G20: =I19 -> #REF! | H20: =E20 -> #REF! | I20: =G20+H20 -> #REF!
B21: June | C21: =($D$13*$D$14)+$D$16 -> #REF! | D21: =$D$13*$D$15 -> 0 | E21: =D21-C21 -> #REF! | G21: =I20 -> #REF! | H21: =E21 -> #REF! | I21: =G21+H21 -> #REF!
B22: July | C22: =($D$13*$D$14)+$D$16 -> #REF! | D22: =$D$13*$D$15 -> 0 | E22: =D22-C22 -> #REF! | G22: =I21 -> #REF! | H22: =E22 -> #REF! | I22: =G22+H22 -> #REF!
B23: August | C23: =($D$13*$D$14)+$D$16 -> #REF! | D23: =$D$13*$D$15 -> 0 | E23: =D23-C23 -> #REF! | G23: =I22 -> #REF! | H23: =E23 -> #REF! | I23: =G23+H23 -> #REF!
B24: September | C24: =($D$13*$D$14)+$D$16 -> #REF! | D24: =$D$13*$D$15 -> 0 | E24: =D24-C24 -> #REF! | G24: =I23 -> #REF! | H24: =E24 -> #REF! | I24: =G24+H24 -> #REF!
B25: October | C25: =($D$13*$D$14)+$D$16 -> #REF! | D25: =$D$13*$D$15 -> 0 | E25: =D25-C25 -> #REF! | G25: =I24 -> #REF! | H25: =E25 -> #REF! | I25: =G25+H25 -> #REF!
B26: November | C26: =($D$13*$D$14)+$D$16 -> #REF! | D26: =$D$13*$D$15 -> 0 | E26: =D26-C26 -> #REF! | G26: =I25 -> #REF! | H26: =E26 -> #REF! | I26: =G26+H26 -> #REF!
B27: December | C27: =($D$13*$D$14)+$D$16 -> #REF! | D27: =$D$13*$D$15 -> 0 | E27: =D27-C27 -> #REF! | G27: =I26 -> #REF! | H27: =E27 -> #REF! | I27: =G27+H27 -> #REF!
B28: January | C28: =($D$13*$D$14)+$D$16 -> #REF! | D28: =$D$13*$D$15 -> 0 | E28: =D28-C28 -> #REF! | G28: =I27 -> #REF! | H28: =E28 -> #REF! | I28: =G28+H28 -> #REF!
B29: February | C29: =($D$13*$D$14)+$D$16 -> #REF! | D29: =$D$13*$D$15 -> 0 | E29: =D29-C29 -> #REF! | G29: =I28 -> #REF! | H29: =E29 -> #REF! | I29: =G29+H29 -> #REF!
B30: March | C30: =($D$13*$D$14)+$D$16 -> #REF! | D30: =$D$13*$D$15 -> 0 | E30: =D30-C30 -> #REF! | G30: =I29 -> #REF! | H30: =E30 -> #REF! | I30: =G30+H30 -> #REF!
C31: =SUM(C19:C30) -> #REF! | D31: =SUM(D19:D30) -> 0 | E31: =D31-C31 -> #REF!
B33: Buffer Capital (Production Cost of 1.5 Months) | D33: =C19*1.5 -> #REF!
B35: Total Yearly Turnover | D35: =D31 -> 0
B36: Initial Working Capital | D36: =C19+D33 -> #REF! | E36: * Working Capital Required=Cash outflow for the first month + Contingency fund
B37: Working Capital Rotation | D37: =D35/D36 -> #REF!
B40: LACTATION POWDER
B42: Monthly Boxes Produced (in Units) | D42: ='Year 3'!C26/12 -> 0
B43: Cost/Box (in ₹) | D43: ='Year 2'!D5 -> #REF!
B44: Revenue/Box (in ₹) | D44: ='Year 2'!D6 -> 286
B45: Monthly Indirect Expense (in ₹) | D45: =('Year 2'!$E$88/12)/4 -> 0
G46: * The working capital that we are investing in the first month is derived from the cash outflow that is required in the first month
B47: Month | C47: Cash Outflow | D47: Cash Inflow | E47: Difference (CO-CI) | G47: Opening W.C. | H47: Net Cash Flow | I47: Closing W.C.
B48: April | C48: =($D$42*$D$43)+$D$45 -> #REF! | D48: =$D$42*$D$44 -> 0 | E48: =D48-C48 -> #REF! | G48: =C48+D62 -> #REF! | H48: =E48 -> #REF! | I48: =G48+H48 -> #REF!
...

Sheet PP BOM
B2: RAW MATERIAL COST
B4: Item No. | C4: Ingredient Name | D4: In Grams | F4: In Rupees
D5: Quantity Per 100 g | E5: Quantity per 500 gm | F5: Rate / Kg | G5: Rate / Gram | H5: Rate Per 500 g
B6: 1 | C6: Skimmed Milk Powder | D6: 35 | E6: =D6*5 -> 175 | F6: 320 | G6: =F6/1000 -> 0.32 | H6: =E6*G6 -> 56
B7: 2 | C7: Maltodextrin | D7: 23.84 | E7: =D7*5 -> 119.2 | F7: 70 | G7: =F7/1000 -> 0.07 | H7: =E7*G7 -> 8.344
B8: 3 | C8: Fructooligosaccharides | D8: 5 | E8: =D8*5 -> 25 | F8: 170 | G8: =F8/1000 -> 0.17 | H8: =E8*G8 -> 4.25
B9: 4 | C9: Rice Protein | D9: 7 | E9: =D9*5 -> 35 | F9: 270 | G9: =F9/1000 -> 0.27 | H9: =E9*G9 -> 9.45
B10: 5 | C10: Soy Protein | D10: 13 | E10: =D10*5 -> 65 | F10: 290 | G10: =F10/1000 -> 0.29 | H10: =E10*G10 -> 18.85
B11: 6 | C11: Shingada Flour | D11: 2 | E11: =D11*5 -> 10 | F11: 190 | G11: =F11/1000 -> 0.19 | H11: =E11*G11 -> 1.9
B12: 7 | C12: Cocoa Powder | D12: 8 | E12: =D12*5 -> 40 | F12: 600 | G12: =F12/1000 -> 0.6 | H12: =E12*G12 -> 24 | I12: 1 | J12: KESAR PISTA
B13: 8 | C13: Vitamin and Mineral Premix | D13: 3.5 | E13: =D13*5 -> 17.5 | F13: 850 | G13: =F13/1000 -> 0.85 | H13: =E13*G13 -> 14.875 | I13: 2 | J13: CHOCOLATE
B14: 9 | C14: Culture | D14: 0.1 | E14: =D14*5 -> 0.5 | F14: 480 | G14: =F14/1000 -> 0.48 | H14: =E14*G14 -> 0.24
B15: 10 | C15: Sucralose | D15: 0.06 | E15: =D15*5 -> 0.3 | F15: 1450 | G15: =F15/1000 -> 1.45 | H15: =E15*G15 -> 0.435
B16: 11 | C16: Nature Identical Flavour | D16: 2 | E16: =D16*5 -> 10 | F16: 700 | G16: =F16/1000 -> 0.7 | H16: =E16*G16 -> 7 | J16: KG | K16: BOXES | L16: COST
B17: 12 | C17: Multisense | D17: 0.5 | E17: =D17*5 -> 2.5 | F17: 2500 | G17: =F17/1000 -> 2.5 | H17: =E17*G17 -> 6.25 | J17: =(K17*500)/1000 -> 400 | K17: 800 | L17: =K17*H25 -> 142875.2 | M17: COGS_ Preg
D18: =SUM(D6:D17) -> 100 | E18: =SUM(E6:E17) -> 500 | H18: =SUM(H6:H17) -> 151.594 | J18: =(K18*500)/1000 -> 400 | K18: 800 | L18: =K18*'LP BOM'!H28 -> 127068 | M18: COGS_Lact
J19: =J17+J18 -> 800 | K19: =K17+K18 -> 1600 | L19: =L17+L18 -> 269943.2 | M19: TOTAL
B20: OTHER COSTS
C22: Packaging cost | H22: 20
C23: Conversion cost | H23: ='Contract (1 yr)'!C43 -> 7
F25: TOTAL COST / BOX | H25: =SUM(H18:H23) -> 178.594
F27: COST / BATCH | H27: 20000000
F29: BOXES / BATCH | H29: =H27/H25 -> 111985.85
F31: AS PER PROJETIONS SHEET
F32: Total Cost (Excl. GST) | H32: =IFERROR(__xludf.DUMMYFUNCTION("importrange(""https://docs.google.com/spreadsheets/d/1DXOBRjKEc9pOcmohKWx0l59g3hrSjk2ZicxFB9zphD4/edit?gid=1408855594#gid=1408855594"",""COGS Breakup!C70:C72"")"),"#REF!") -> #REF! | I32: VS | J32: =H25 -> 178.594
F33: GST 18%
F34: Total Cost (Incl. GST)
B37: Mawa Kulfi
B38: Item No. | C38: Ingredient Name | D38: In Grams | F38: In Rupees
D39: Quantity Per 100 g | E39: Quantity per 500 gm | F39: Rate / Kg | G39: Rate / Gram | H39: Rate Per 500 g
B40: 1 | C40: Skimmed Milk Powder | D40: 36 | E40: =D40*5 -> 180 | F40: 240 | G40: =F40/1000 -> 0.24 | H40: =E40*G40 -> 43.2
B41: 2 | C41: Maltodextrin | D41: 27.84 | E41: =D41*5 -> 139.2 | F41: 70 | G41: =F41/1000 -> 0.07 | H41: =E41*G41 -> 9.744
B42: 3 | C42: Fructooligosaccharides | D42: 5 | E42: =D42*5 -> 25 | F42: 170 | G42: =F42/1000 -> 0.17 | H42: =E42*G42 -> 4.25
B43: 4 | C43: Rice Protein | D43: 8 | E43: =D43*5 -> 40 | F43: 270 | G43: =F43/1000 -> 0.27 | H43: =E43*G43 -> 10.8
B44: 5 | C44: Soy Protein | D44: 15 | E44: =D44*5 -> 75 | F44: 290 | G44: =F44/1000 -> 0.29 | H44: =E44*G44 -> 21.75
B45: 6 | C45: Shingada Flour | D45: 2 | E45: =D45*5 -> 10 | F45: 190 | G45: =F45/1000 -> 0.19 | H45: =E45*G45 -> 1.9
B46: 7 | D46: 0 | E46: =D46*5 -> 0 | F46: 600 | G46: =F46/1000 -> 0.6 | H46: =E46*G46 -> 0
B47: 8 | C47: Vitamin and Mineral Premix | D47: 3.5 | E47: =D47*5 -> 17.5 | F47: 850 | G47: =F47/1000 -> 0.85 | H47: =E47*G47 -> 14.875
B48: 9 | C48: Culture | D48: 0.1 | E48: =D48*5 -> 0.5 | F48: 480 | G48: =F48/1000 -> 0.48 | H48: =E48*G48 -> 0.24
B49: 10 | C49: Sucralose | D49: 0.06 | E49: =D49*5 -> 0.3 | F49: 1300 | G49: =F49/1000 -> 1.3 | H49: =E49*G49 -> 0.39
...

Sheet LP BOM
B2: RAW MATERIAL COST
B4: Item No. | C4: Ingredient Name | D4: In Grams | F4: In Rupees
D5: Quantity Per 100 g | E5: Quantity per 500 gm | F5: Rate / Kg | G5: Rate / Gram | H5: Rate Per 500 g
B6: 1 | C6: Skimmed Milk Powder | D6: 35.5 | E6: =D6*5 -> 177.5 | F6: 320 | G6: =F6/1000 -> 0.32 | H6: =E6*G6 -> 56.8
B7: 2 | C7: Maltodextrin | D7: 24.85 | E7: =D7*5 -> 124.25 | F7: 70 | G7: =F7/1000 -> 0.07 | H7: =E7*G7 -> 8.6975
B8: 3 | C8: Fructooligosaccharides | D8: 5 | E8: =D8*5 -> 25 | F8: 170 | G8: =F8/1000 -> 0.17 | H8: =E8*G8 -> 4.25
B9: 4 | C9: Rice Protein | D9: 8 | E9: =D9*5 -> 40 | F9: 270 | G9: =F9/1000 -> 0.27 | H9: =E9*G9 -> 10.8 | I9: 1 | J9: MAWA KULFI
B10: 5 | C10: Soy Protein | D10: 15 | E10: =D10*5 -> 75 | F10: 290 | G10: =F10/1000 -> 0.29 | H10: =E10*G10 -> 21.75 | I10: 2 | J10: VANILA
B11: 6 | C11: Shingada Flour | D11: 2 | E11: =D11*5 -> 10 | F11: 180 | G11: =F11/1000 -> 0.18 | H11: =E11*G11 -> 1.8
B12: 7 | C12: Vitamin and Mineral premix | D12: 3.5 | E12: =D12*5 -> 17.5 | F12: 800 | G12: =F12/1000 -> 0.8 | H12: =E12*G12 -> 14
B13: 8 | C13: Culture | D13: 0.1 | E13: =D13*5 -> 0.5 | F13: 450 | G13: =F13/1000 -> 0.45 | H13: =E13*G13 -> 0.225
B14: 9 | C14: Sucralose | D14: 0.05 | E14: =D14*5 -> 0.25 | F14: 1450 | G14: =F14/1000 -> 1.45 | H14: =E14*G14 -> 0.3625
B15: 10 | C15: Nature Identical Flavour Cardamom | D15: 1.5 | E15: =D15*5 -> 7.5 | F15: 700 | G15: =F15/1000 -> 0.7 | H15: =E15*G15 -> 5.25
B16: 11 | C16: Shatavari | D16: 2 | E16: =D16*5 -> 10 | F16: 350 | G16: =F16/1000 -> 0.35 | H16: =E16*G16 -> 3.5
B17: 12 | C17: Ashwagandha | D17: 1 | E17: =D17*5 -> 5 | F17: 650 | G17: =F17/1000 -> 0.65 | H17: =E17*G17 -> 3.25
B18: 13 | C18: Moringa | D18: 0.5 | E18: =D18*5 -> 2.5 | F18: 180 | G18: =F18/1000 -> 0.18 | H18: =E18*G18 -> 0.45
B19: 14 | C19: Funnel | D19: 0.5 | E19: =D19*5 -> 2.5 | F19: 180 | G19: =F19/1000 -> 0.18 | H19: =E19*G19 -> 0.45
B20: 15 | C20: Cinnamon | D20: 0.5 | E20: =D20*5 -> 2.5 | F20: 100 | G20: =F20/1000 -> 0.1 | H20: =E20*G20 -> 0.25
D21: =SUM(D6:D20) -> 100 | E21: =SUM(E6:E20) -> 500 | H21: =SUM(H6:H20) -> 131.835
B23: OTHER COSTS
C25: Packaging cost | H25: 20
C26: Conversion cost | H26: ='Contract (1 yr)'!C43 -> 7
F28: TOTAL COST / BOX | H28: =sum(H21:H26) -> 158.835 | K28: =H28*800 -> 127068 | L28: - COST OF 400 Boxes
F30: PRODUCTION COST / BATCH | H30: 20000000
F32: BOXES / BATCH | H32: =H30/H28 -> 125916.83
F34: AS PER PROJETIONS SHEET
F35: Total Cost (Excl. GST) | H35: =IFERROR(__xludf.DUMMYFUNCTION("importrange(""https://docs.google.com/spreadsheets/d/1DXOBRjKEc9pOcmohKWx0l59g3hrSjk2ZicxFB9zphD4/edit?gid=1408855594#gid=1408855594"",""COGS Breakup!C103:C105"")"),"#REF!") -> #REF! | I35: VS | J35: =H28 -> 158.835
F36: GST 18%
F37: Total Cost (Incl. GST)
C39: Kesar
B40: Item No. | C40: Ingredient Name | D40: In Grams | F40: In Rupees
D41: Quantity Per 100 g | E41: Quantity per 500 gm | F41: Rate / Kg | G41: Rate / Gram | H41: Rate Per 500 g
B42: 1 | C42: Skimmed Milk Powder | D42: 35 | E42: =D42*5 -> 175 | F42: 240 | G42: =F42/1000 -> 0.24 | H42: =E42*G42 -> 42
B43: 2 | C43: Maltodextrin | D43: 25 | E43: =D43*5 -> 125 | F43: 50 | G43: =F43/1000 -> 0.05 | H43: =E43*G43 -> 6.25
B44: 3 | C44: Fructooligosaccharides | D44: 5 | E44: =D44*5 -> 25 | F44: 170 | G44: =F44/1000 -> 0.17 | H44: =E44*G44 -> 4.25
B45: 4 | C45: Rice Protein | D45: 8.35 | E45: =D45*5 -> 41.75 | F45: 270 | G45: =F45/1000 -> 0.27 | H45: =E45*G45 -> 11.2725
B46: 5 | C46: Soy Protein | D46: 15 | E46: =D46*5 -> 75 | F46: 290 | G46: =F46/1000 -> 0.29 | H46: =E46*G46 -> 21.75
B47: 6 | C47: Shingada Flour | D47: 2 | E47: =D47*5 -> 10 | F47: 180 | G47: =F47/1000 -> 0.18 | H47: =E47*G47 -> 1.8
B48: 7 | C48: Vitamin and Mineral premix | D48: 3.5 | E48: =D48*5 -> 17.5 | F48: 800 | G48: =F48/1000 -> 0.8 | H48: =E48*G48 -> 14
B49: 8 | C49: Culture | D49: 0.1 | E49: =D49*5 -> 0.5 | F49: 450 | G49: =F49/1000 -> 0.45 | H49: =E49*G49 -> 0.225
...

Sheet IFM BOM
B2: RAW MATERIAL COST
B4: Item No. | C4: Ingredient Name | D4: In Grams | F4: In Rupees
D5: Quantity Per 100 g | E5: Quantity per 400 gm | F5: Rate / Kg | G5: Rate / Gram | H5: Rate Per 400 g
B6: 1 | C6: Skim Milk Powder | D6: 35 | E6: =D6*4 -> 140 | F6: 320 | G6: =F6/1000 -> 0.32 | H6: =E6*G6 -> 44.8
B7: 2 | C7: Demineralised Whey Powder | D7: 22 | E7: =D7*4 -> 88 | F7: 150 | G7: =F7/1000 -> 0.15 | H7: =E7*G7 -> 13.2
B8: 3 | C8: Lactose | D8: 13 | E8: =D8*4 -> 52 | F8: 200 | G8: =F8/1000 -> 0.2 | H8: =E8*G8 -> 10.4
B9: 4 | C9: Maltodextrin | D9: 8.05 | E9: =D9*4 -> 32.2 | F9: 70 | G9: =F9/1000 -> 0.07 | H9: =E9*G9 -> 2.254
B10: 5 | C10: High Oleic Sunflower Oil | D10: 6 | E10: =D10*4 -> 24 | F10: 350 | G10: =F10/1000 -> 0.35 | H10: =E10*G10 -> 8.4
B11: 6 | C11: Soya oil Powder | D11: 4 | E11: =D11*4 -> 16 | F11: 100 | G11: =F11/1000 -> 0.1 | H11: =E11*G11 -> 1.6
B12: 7 | C12: Coconut oil Powder | D12: 2 | E12: =D12*4 -> 8 | F12: 250 | G12: =F12/1000 -> 0.25 | H12: =E12*G12 -> 2
B13: 8 | C13: Milk fat powder | D13: 4 | E13: =D13*4 -> 16 | F13: 230 | G13: =F13/1000 -> 0.23 | H13: =E13*G13 -> 3.68
B14: 9 | C14: DHA oil Powder | D14: 0.2 | E14: =D14*4 -> 0.8 | F14: 400 | G14: =F14/1000 -> 0.4 | H14: =E14*G14 -> 0.32
B15: 10 | C15: ARA oil Powder | D15: 0.2 | E15: =D15*4 -> 0.8 | F15: 150 | G15: =F15/1000 -> 0.15 | H15: =E15*G15 -> 0.12
B16: 11 | C16: Fructooligosaccharides | D16: 2 | E16: =D16*4 -> 8 | F16: 170 | G16: =F16/1000 -> 0.17 | H16: =E16*G16 -> 1.36
B17: 12 | C17: Galactooligosaccharides | D17: 1.5 | E17: =D17*4 -> 6 | F17: 200 | G17: =F17/1000 -> 0.2 | H17: =E17*G17 -> 1.2
... B22: 17 | C22: L-Carnitine | D22: 0.05 | E22: =D22*4 -> 0.2 | F22: 2000 | G22: =F22/1000 -> 2 | H22: =E22*G22 -> 0.4
B23: RAW MATERIAL TOTAL COST | D23: =SUM(D6:D22) -> 100.008 | E23: =D23*5 -> 500.04 | H23: =SUM(H6:H22) -> 92.9836
B25: OTHER COSTS
C27: Packaging | H27: 20
C28: Conversion | H28: ='Contract (1 yr)'!C51 -> 11.2
F30: TOTAL COST / BOX | H30: =H23+H27+H28 -> 124.1836
F32: PRODUCTION COST / BATCH | H32: 20000000
F34: BOXES / BATCH | H34: =H32/H30 -> 161051.86
F36: BOXES / VARIANT | H36: =H34/3 -> 53683.954
F38: AS PER PROJETIONS SHEET
F39: Total Cost (Excl. GST) | H39: =IFERROR(__xludf.DUMMYFUNCTION("importrange(""https://docs.google.com/spreadsheets/d/1bEcp3VCHzQgxan8VY9FCqLk1Yk8qAjekoqv5jLH-RCM/edit?gid=1653862983#gid=1653862983"",""COGS Breakup!C69:C71"")"),"#REF!") -> #REF! | I39: VS | J39: =H30 -> 124.1836
F40: GST 18%
F41: Total Cost (Incl. GST)

Sheet CNP BOM
B2: RAW MATERIAL COST
B4: Item No. | C4: Ingredient Name | D4: In Grams | F4: In Rupees
D5: Quantity Per 100 g | E5: Quantity per 400 gm | F5: Rate / Kg | G5: Rate / Gram | H5: Rate Per 400 g
B6: 1 | C6: Skimmed Milk Powder | D6: 35 | E6: =D6*4 -> 140 | F6: 320 | G6: =F6/1000 -> 0.32 | H6: =E6*G6 -> 44.8
B7: 2 | C7: Maltodextrin | D7: 14 | E7: =D7*4 -> 56 | F7: 70 | G7: =F7/1000 -> 0.07 | H7: =E7*G7 -> 3.92
B8: 3 | C8: Nuts blend(Almond, Cashew, Walnut, Pista, Dates) | D8: 6 | E8: =D8*4 -> 24 | F8: 180 | G8: =F8/1000 -> 0.18 | H8: =E8*G8 -> 4.32
B9: 4 | C9: Cocoa powder | D9: 6 | E9: =D9*4 -> 24 | F9: 600 | G9: =F9/1000 -> 0.6 | H9: =E9*G9 -> 14.4 | I9: 1 | J9: VANILLA
B10: 5 | C10: Palmyra Jaggery | D10: 13 | E10: =D10*4 -> 52 | F10: 50 | G10: =F10/1000 -> 0.05 | H10: =E10*G10 -> 2.6 | I10: 2 | J10: CHOCOLATE
B11: 6 | C11: Fructooligosaccharides | D11: 2 | E11: =D11*4 -> 8 | F11: 170 | G11: =F11/1000 -> 0.17 | H11: =E11*G11 -> 1.36
B12: 7 | C12: Nature Identical Flavours | D12: 2 | E12: =D12*4 -> 8 | F12: 600 | G12: =F12/1000 -> 0.6 | H12: =E12*G12 -> 4.8
B13: 8 | C13: Vitamins | D13: 1 | E13: =D13*4 -> 4 | F13: 500 | G13: =F13/1000 -> 0.5 | H13: =E13*G13 -> 2
B14: 9 | C14: Minerals | D14: 1 | E14: =D14*4 -> 4 | F14: 400 | G14: =F14/1000 -> 0.4 | H14: =E14*G14 -> 1.6
B15: 10 | C15: Fruit Powder | D15: 12 | E15: =D15*4 -> 48 | F15: 200 | G15: =F15/1000 -> 0.2 | H15: =E15*G15 -> 9.6
B16: 11 | C16: Ragi Powder | D16: 8 | E16: =D16*4 -> 32 | F16: 40 | G16: =F16/1000 -> 0.04 | H16: =E16*G16 -> 1.28
D17: =SUM(D6:D16) -> 100 | E17: =D17*4 -> 400 | H17: =SUM(H6:H16) -> 90.68
B19: OTHER COSTS
C21: Packaging Cost | H21: 20
C22: Conversion cost | H22: ='Contract (1 yr)'!C51 -> 11.2
F24: TOTAL COST / BOX | H24: =sum(H17:H22) -> 121.88
F26: PRODUCTION COST / BATCH | H26: 20000000
F28: BOXES / BATCH | H28: =H26/H24 -> 164095.83
F30: AS PER PROJETIONS SHEET
F31: Total Cost (Excl. GST) | H31: =IFERROR(__xludf.DUMMYFUNCTION("importrange(""https://docs.google.com/spreadsheets/d/1bEcp3VCHzQgxan8VY9FCqLk1Yk8qAjekoqv5jLH-RCM/edit?gid=1653862983#gid=1653862983"",""COGS Breakup!C102:C104"")"),"#REF!") -> #REF! | I31: VS | J31: =H24 -> 121.88
F32: GST 18%
F33: Total Cost (Incl. GST)

Sheet Product Line
B2: * SKUs may vary from year to year due to addition of new flavours (Currently 1-2 flavours of each Variant)
B3: Years | C3: All Products | D3: Tier
B4: Year 1 | C4: 4
C5: Pregnancy Powder | D5: 3
C6: Lactation Powder | D6: 3
C7: Infant Powder | D7: 3
C8: Children Powder | D8: 3
B10: Year 2 | C10: =COUNTA(C11:C24) -> 14
C11: Pregnancy Powder- Trimester 1 | D11: 1
C12: Pregnancy Powder- Trimester 2 | D12: 1
C13: Pregnancy Powder- Trimester 3 | D13: 1
C14: Lactation Powder | D14: 1
C15: Infant Formula Powder- 0 to 6m | D15: 1
C16: Infant Formula Powder- 6 to 12m | D16: 1
C17: Infant Formula Powder- 12 to 24m | D17: 1
C18: Infant Complementary Food- 6 to 12m | D18: 1
C19: Infant Complementary Food- 12 to 24m | D19: 1
C20: Children Powder | D20: 1
C21: Pregnancy Powder | D21: 3
C22: Lactation Powder | D22: 3
... C24: Children Powder | D24: 3
B26: Year 3 | C26: =counta(C27:C50) -> 24
C27: Pregnancy Powder- Trimester 1 | D27: 1
C28: Pregnancy Powder- Trimester 2 | D28: 1
C29: Pregnancy Powder- Trimester 3 | D29: 1
C30: Lactation Powder | D30: 1
C31: Infant Formula Powder- 0 to 6m | D31: 1
C32: Infant Formula Powder- 6 to 12m | D32: 1
C33: Infant Formula Powder- 12 to 24m | D33: 1
C34: Infant Complementary Food- 6 to 12m | D34: 1
C35: Infant Complementary Food- 12 to 24m | D35: 1
C36: Children Powder | D36: 1
C37: Pregnancy Powder- Trimester 1 | D37: 2
C38: Pregnancy Powder- Trimester 2 | D38: 2
... C50: Children Powder | D50: 3
B52: Year 4 | C52: =counta(C53:C76) -> 24
C53: Pregnancy Powder- Trimester 1 | D53: 1
C54: Pregnancy Powder- Trimester 2 | D54: 1
C55: Pregnancy Powder- Trimester 3 | D55: 1
C56: Lactation Powder | D56: 1
...

Sheet Strategy
H5: Years | I5: 1 | J5: 2 | K5: 3 | L5: 4 | M5: 5
H6: Tiers Targetted | I6: Tier 3 | J6: Tier 1 & 3 | K6: All Tiers | L6: All Tiers | M6: All Tiers
H7: Investor Capital Deployed (in Cr) | I7: 22 | J7: 60 | K7: 220 | L7: 0 | M7: 0
H8: Products (SKUs) | I8: ='Product Line'!C4 -> 4 | J8: ='Product Line'!C10 -> 14 | K8: ='Product Line'!C26 -> 24 | L8: =K8 -> 24 | M8: =L8 -> 24
H9: Manufacturing | I9: Contract Manufacturing | J9: In-house & Third Party Manufacturing | K9: In-house & Third Party Manufacturing | L9: In-house & Third Party Manufacturing | M9: In-house & Third Party Manufacturing
H10: Plants Set up | I10: ='In-house (2-5yrs)'!C3 -> 0 | J10: ='In-house (2-5yrs)'!C4 -> 1 | K10: ='In-house (2-5yrs)'!C5 -> 2 | L10: ='In-house (2-5yrs)'!C6 -> 3 | M10: ='In-house (2-5yrs)'!C7 -> 3
H11: Total Plants | I11: =I10 -> 0 | J11: =J10+I11 -> 1 | K11: =K10+J11 -> 3 | L11: =L10+K11 -> 6 | M11: =M10+L11 -> 9

Sheet P&L
G2: Rs. in cr
B3: YEARS | C3: 1 | D3: 2 | E3: 3 | F3: 4 | G3: 5
B5: REVENUE
B6: Revenue from Operation | C6: ='Contract (1 yr)'!E27 -> 88.413 | D6: ='In-house (2-5yrs)'!F4+'Third Party (2-5yrs)'!R4 -> #REF! | E6: ='In-house (2-5yrs)'!F5+'Third Party (2-5yrs)'!R5 -> #REF! | F6: ='In-house (2-5yrs)'!F6+'Third Party (2-5yrs)'!R6 -> #REF! | G6: ='In-house (2-5yrs)'!F7+'Third Party (2-5yrs)'!R7 -> #REF!
B7: Pregnancy Powder- Trimester 1- Tier 1 | D7: =('In-house (2-5yrs)'!$C$20/3)/10^7 -> #REF! | E7: =('In-house (2-5yrs)'!$C$21/10^7)/3 -> #REF! | F7: =('In-house (2-5yrs)'!$C$22/10^7)/3 -> #REF! | G7: ='In-house (2-5yrs)'!$C$23/10^7/3 -> #REF!
B8: Pregnancy Powder- Trimester 2- Tier 1 | D8: =('In-house (2-5yrs)'!$C$20/3)/10^7 -> #REF! | E8: =('In-house (2-5yrs)'!$C$21/10^7)/3 -> #REF! | F8: =('In-house (2-5yrs)'!$C$22/10^7)/3 -> #REF! | G8: ='In-house (2-5yrs)'!$C$23/10^7/3 -> #REF!
B9: Pregnancy Powder- Trimester 3- Tier 1 | D9: =('In-house (2-5yrs)'!$C$20/3)/10^7 -> #REF! | E9: =('In-house (2-5yrs)'!$C$21/10^7)/3 -> #REF! | F9: =('In-house (2-5yrs)'!$C$22/10^7)/3 -> #REF! | G9: ='In-house (2-5yrs)'!$C$23/10^7/3 -> #REF!
B10: Lactation Powder- Tier 1 | D10: ='In-house (2-5yrs)'!F20/10^7 -> 0 | E10: ='In-house (2-5yrs)'!F21/10^7 -> 0 | F10: ='In-house (2-5yrs)'!F22/10^7 -> 0 | G10: ='In-house (2-5yrs)'!F23/10^7 -> 0
B11: Infant Formula Powder- 0 to 6m- Tier 1 | D11: =('In-house (2-5yrs)'!$D$97*'In-house (2-5yrs)'!$I$12)/10^7/5 -> #REF! | E11: =('In-house (2-5yrs)'!$I$21/10^7)/5 -> #REF! | F11: =('In-house (2-5yrs)'!$I$22/10^7)/5 -> #REF! | G11: ='In-house (2-5yrs)'!$I$23/10^7/5 -> #REF!
B12: Infant Formula Powder- 6 to 12m- Tier 1 | D12: =('In-house (2-5yrs)'!$D$97*'In-house (2-5yrs)'!$I$12)/10^7/5 -> #REF! | E12: =('In-house (2-5yrs)'!$I$21/10^7)/5 -> #REF! | F12: =('In-house (2-5yrs)'!$I$22/10^7)/5 -> #REF! | G12: ='In-house (2-5yrs)'!$I$23/10^7/5 -> #REF!
B13: Infant Formula Powder- 12 to 24m- Tier 1 | D13: =('In-house (2-5yrs)'!$D$97*'In-house (2-5yrs)'!$I$12)/10^7/5 -> #REF! | E13: =('In-house (2-5yrs)'!$I$21/10^7)/5 -> #REF! | F13: =('In-house (2-5yrs)'!$I$22/10^7)/5 -> #REF! | G13: ='In-house (2-5yrs)'!$I$23/10^7/5 -> #REF!
B14: Infant Complementary Food- 6 to 12m- Tier 1 | D14: =('In-house (2-5yrs)'!$D$97*'In-house (2-5yrs)'!$I$12)/10^7/5 -> #REF! | E14: =('In-house (2-5yrs)'!$I$21/10^7)/5 -> #REF! | F14: =('In-house (2-5yrs)'!$I$22/10^7)/5 -> #REF! | G14: ='In-house (2-5yrs)'!$I$23/10^7/5 -> #REF!
B15: Infant Complementary Food- 12 to 24m- Tier 1 | D15: =('In-house (2-5yrs)'!$D$97*'In-house (2-5yrs)'!$I$12)/10^7/5 -> #REF! | E15: =('In-house (2-5yrs)'!$I$21/10^7)/5 -> #REF! | F15: =('In-house (2-5yrs)'!$I$22/10^7)/5 -> #REF! | G15: ='In-house (2-5yrs)'!$I$23/10^7/5 -> #REF!
B16: Children Powder- Tier 1 | D16: =('In-house (2-5yrs)'!L12*'In-house (2-5yrs)'!D100)/10^7 -> 0 | E16: ='In-house (2-5yrs)'!L21/10^7 -> 0 | F16: ='In-house (2-5yrs)'!L22/10^7 -> 0 | G16: ='In-house (2-5yrs)'!L23/10^7 -> 0
B17: Pregnancy Powder- Trimester 1- Tier 2 | E17: =('In-house (2-5yrs)'!$D$21/10^7)/3 -> 0 | F17: ='In-house (2-5yrs)'!$D$22/10^7/3 -> 0 | G17: ='In-house (2-5yrs)'!$D$23/10^7/3 -> 0
B18: Pregnancy Powder- Trimester 2- Tier 2 | E18: =('In-house (2-5yrs)'!$D$21/10^7)/3 -> 0 | F18: ='In-house (2-5yrs)'!$D$22/10^7/3 -> 0 | G18: ='In-house (2-5yrs)'!$D$23/10^7/3 -> 0
B19: Pregnancy Powder- Trimester 3- Tier 2 | E19: =('In-house (2-5yrs)'!$D$21/10^7)/3 -> 0 | F19: ='In-house (2-5yrs)'!$D$22/10^7/3 -> 0 | G19: ='In-house (2-5yrs)'!$D$23/10^7/3 -> 0
B20: Lactation Powder- Tier 2 | E20: ='In-house (2-5yrs)'!G21/10^7 -> 0 | F20: ='In-house (2-5yrs)'!G22/10^7 -> 0 | G20: ='In-house (2-5yrs)'!G23/10^7 -> 0
B21: Infant Formula Powder- 0 to 6m- Tier 2 | E21: =('In-house (2-5yrs)'!$J$21/10^7)/5 -> 0 | F21: ='In-house (2-5yrs)'!$J$22/10^7/5 -> 0 | G21: ='In-house (2-5yrs)'!$J$23/10^7/5 -> 0
B22: Infant Formula Powder- 6 to 12m- Tier 2 | E22: =('In-house (2-5yrs)'!$J$21/10^7)/5 -> 0 | F22: ='In-house (2-5yrs)'!$J$22/10^7/5 -> 0 | G22: ='In-house (2-5yrs)'!$J$23/10^7/5 -> 0
B23: Infant Formula Powder- 12 to 24m- Tier 2 | E23: =('In-house (2-5yrs)'!$J$21/10^7)/5 -> 0 | F23: ='In-house (2-5yrs)'!$J$22/10^7/5 -> 0 | G23: ='In-house (2-5yrs)'!$J$23/10^7/5 -> 0
B24: Infant Complementary Food- 6 to 12m- Tier 2 | E24: =('In-house (2-5yrs)'!$J$21/10^7)/5 -> 0 | F24: ='In-house (2-5yrs)'!$J$22/10^7/5 -> 0 | G24: ='In-house (2-5yrs)'!$J$23/10^7/5 -> 0
B25: Infant Complementary Food- 12 to 24m- Tier 2 | E25: =('In-house (2-5yrs)'!$J$21/10^7)/5 -> 0 | F25: ='In-house (2-5yrs)'!$J$22/10^7/5 -> 0 | G25: ='In-house (2-5yrs)'!$J$23/10^7/5 -> 0
B26: Children Powder- Tier 2 | E26: ='In-house (2-5yrs)'!M21/10^7 -> 0 | F26: ='In-house (2-5yrs)'!M22/10^7 -> 0 | G26: ='In-house (2-5yrs)'!M23/10^7 -> 0
B27: Pregnancy Powder- Tier 3 | C27: ='Contract (1 yr)'!E25 -> 21.84 | D27: =('In-house (2-5yrs)'!E12*'In-house (2-5yrs)'!D93)/10^7 -> 0 | E27: ='In-house (2-5yrs)'!E21/10^7 -> 0 | F27: ='In-house (2-5yrs)'!E22/10^7 -> 0 | G27: ='In-house (2-5yrs)'!E23/10^7 -> 0
B28: Lactation Powder- Tier 3 | C28: ='Contract (1 yr)'!E26 -> 22.308 | D28: =('In-house (2-5yrs)'!D96*'In-house (2-5yrs)'!H12)/10^7 -> 0 | E28: ='In-house (2-5yrs)'!H21/10^7 -> 0 | F28: ='In-house (2-5yrs)'!H22/10^7 -> 0 | G28: ='In-house (2-5yrs)'!H23/10^7 -> 0
B29: Infant Powder- Tier 3 | C29: ='Contract (1 yr)'!E23 -> 23.595 | D29: =('In-house (2-5yrs)'!K12*'In-house (2-5yrs)'!D99)/10^7 -> 0 | E29: ='In-house (2-5yrs)'!K21/10^7 -> 0 | F29: ='In-house (2-5yrs)'!K22/10^7 -> 0 | G29: ='In-house (2-5yrs)'!K23/10^7 -> 0
B30: Children Powder- Tier 3 | C30: ='Contract (1 yr)'!E24 -> 20.67 | D30: =('In-house (2-5yrs)'!D102*'In-house (2-5yrs)'!N12)/10^7 -> 0 | E30: ='In-house (2-5yrs)'!N21/10^7 -> 0 | F30: ='In-house (2-5yrs)'!N22/10^7 -> 0 | G30: ='In-house (2-5yrs)'!N23/10^7 -> 0
B31: Contract Manufacturing | D31: ='Third Party (2-5yrs)'!R4 -> #REF! | E31: ='Third Party (2-5yrs)'!R5 -> #REF! | F31: ='Third Party (2-5yrs)'!R6 -> #REF! | G31: ='Third Party (2-5yrs)'!R7 -> #REF!
B32: Other income | C32: ='Project Financing'!U14 -> 0 | D32: ='Project Financing'!U15 -> #REF! | E32: ='Project Financing'!U16 -> #REF! | F32: ='Project Financing'!U17 -> #REF! | G32: ='Project Financing'!U18 -> #REF!
B33: Total Revenue | C33: =C6+C32 -> 88.413 | D33: =D6+D32 -> #REF! | E33: =E6+E32 -> #REF! | F33: =F6+F32 -> #REF! | G33: =G6+G32 -> #REF!
B34: Revenue Growth % | D34: =(D33-C33)/C33 -> #REF! | E34: =(E33-D33)/D33 -> #REF! | F34: =(F33-E33)/E33 -> #REF! | G34: =(G33-F33)/F33 -> #REF!
B36: COGS | C36: ='Contract (1 yr)'!F27 -> 50.310663 | D36: ='In-house (2-5yrs)'!G4 -> 0 | E36: ='In-house (2-5yrs)'!G5 -> 0 | F36: ='In-house (2-5yrs)'!G6 -> 0 | G36: ='In-house (2-5yrs)'!G7 -> 0
B37: Gross Profit Margin % | C37: =C36/C33 -> 0.56904146 | D37: =D36/D33 -> #REF! | E37: =E36/E33 -> #REF! | F37: =F36/F33 -> #REF! | G37: =G36/G33 -> #REF!
B39: INDIRECT EXPENSES
B40: Marketing & Advertising | C40: =sum('Indirect Expenses'!C56:E56) -> 6.18891 | D40: =sum('Indirect Expenses'!F56:H56) -> #REF! | E40: =sum('Indirect Expenses'!I56:K56) -> #REF! | F40: =sum('Indirect Expenses'!L56:N56) -> #REF! | G40: =sum('Indirect Expenses'!O56:Q56) -> #REF! | H40: * Includes Consumer digital ads, Influencer & KOL marketing, Sampling & trial programs, GTM marketing, Branding, Events, etc
B41: Tier 1 | C41: ='Indirect Expenses'!C56 -> 0 | D41: ='Indirect Expenses'!F56 -> #REF! | E41: ='Indirect Expenses'!I56 -> #REF! | F41: ='Indirect Expenses'!L56 -> #REF! | G41: ='Indirect Expenses'!O56 -> #REF!
B42: Tier 2 | C42: ='Indirect Expenses'!D56 -> 0 | D42: ='Indirect Expenses'!G56 -> 0 | E42: ='Indirect Expenses'!J56 -> 0 | F42: ='Indirect Expenses'!M56 -> 0 | G42: ='Indirect Expenses'!P56 -> 0
B43: Tier 3 | C43: ='Indirect Expenses'!E56 -> 6.18891 | D43: ='Indirect Expenses'!H56 -> 0 | E43: ='Indirect Expenses'!K56 -> 0 | F43: ='Indirect Expenses'!N56 -> 0 | G43: ='Indirect Expenses'!Q56 -> 0
B44: HCP Detailing & Medical Engagement | C44: =sum('Indirect Expenses'!C57:E57) -> 1.76826 | D44: =sum('Indirect Expenses'!F57:H57) -> #REF! | E44: =sum('Indirect Expenses'!I57:K57) -> #REF! | F44: =sum('Indirect Expenses'!L57:N57) -> #REF! | G44: =sum('Indirect Expenses'!O57:Q57) -> #REF! | H44: * OBGYN, Gynecologist, Pediatrician detailing, Hospital & Nursing home tie-ups, Lactation Consultant & Dietitian programs, Medical conference sponsorships
...

Sheet Competitor Brands
B2: Expense Head | C2: Remarks | D2: HealthKart | E2: Kapiva | F2: OZiva | G2: Wellbeing Nutrition | H2: Early Stage Guide
B4: Marketing & brand
B5: Advertising & Promotions | C5: Digital, influencer, trade mktg | D5: 0.2 | E5: 0.55 | F5: 0.47 | G5: ~38% | H5: 30 – 50%
B6: Brand building & design | C6: Identity, packaging, PR | D6: ~3% | E6: ~5% | F6: ~4% | G6: ~5% | H6: 5 – 10%
B7: Doctor detailing & KOL | C7: Esp. critical for pregnancy/infant | D7: N/A | E7: N/A | F7: N/A | G7: N/A | H7: 3 – 6%
B9: Human resources
B10: Employee benefits | C10: Salaries, PF, ESOP | D10: 0.088 | E10: 0.17 | F10: 0.089 | G10: ~15% | H10: 15 – 25%
B12: Sales & distribution
B13: Channel commissions | C13: Amazon, Flipkart, 1mg, pharmacy | D13: 0.062 | E13: ~8% | F13: ~10% | G13: ~10% | H13: 8 – 12%
B14: Logistics & fulfilment | C14: Freight, 3PL, returns | D14: ~4% | E14: ~6% | F14: ~6% | G14: ~7% | H14: 5 – 8%
B16: Overheads & compliance
B17: Legal, regulatory & FSSAI | D17: ~1% | E17: ~2% | F17: ~2% | G17: ~2% | H17: 2 – 4%
B18: IT, SaaS & tech infra | D18: ~1% | E18: ~2% | F18: ~2% | G18: ~2% | H18: 2 – 4%
B19: Rent, utilities & admin | D19: ~2% | E19: ~3% | F19: ~3% | G19: ~4% | H19: 3 – 6%
B21: R&D & product
B22: R&D, testing & FSSAI dossiers | C22: 1.5-2x higher for infant formula | D22: ~1% | E22: ~1% | F22: ~3% | G22: ~4% | H22: 2 – 5%
B24: Profitability summary
B25: Gross margin | D25: ~51% | E25: ~72% | F25: ~73% | G25: ~70% | H25: 45 – 65%
B26: EBITDA margin | D26: =+6% -> 0.06 | E26: -0.21 | F26: -0.012 | G26: ~-5% | H26: -30 to -50%
B27: ₹ spent to earn ₹1 | D27: ₹0.97 | E27: ₹1.22 | F27: ₹1.04 | G27: ~₹1.10 | H27: ₹1.40–1.80

Sheet Revenue Breakup
C2: 1 | E2: 2 | G2: 3 | I2: 4 | K2: 5
B3: Revenue from Operation | C3: ='P&L'!C6 -> 88.413 | D3: =C3/$C$3 -> 1 | E3: ='P&L'!D6 -> #REF! | F3: =E3/$E$3 -> #REF! | G3: ='P&L'!E6 -> #REF! | H3: =G3/$G$3 -> #REF! | I3: ='P&L'!F6 -> #REF! | J3: =I3/$I$3 -> #REF! | K3: ='P&L'!G6 -> #REF! | L3: =K3/$K$3 -> #REF!
B4: Pregnancy Powder- Trimester 1- Tier 1 | C4: ='P&L'!C7 | D4: =C4/$C$3 -> 0 | E4: ='P&L'!D7 -> #REF! | F4: =E4/$E$3 -> #REF! | G4: ='P&L'!E7 -> #REF! | H4: =G4/$G$3 -> #REF! | I4: ='P&L'!F7 -> #REF! | J4: =I4/$I$3 -> #REF! | K4: ='P&L'!G7 -> #REF! | L4: =K4/$K$3 -> #REF!
B5: Pregnancy Powder- Trimester 2- Tier 1 | C5: ='P&L'!C8 | D5: =C5/$C$3 -> 0 | E5: ='P&L'!D8 -> #REF! | F5: =E5/$E$3 -> #REF! | G5: ='P&L'!E8 -> #REF! | H5: =G5/$G$3 -> #REF! | I5: ='P&L'!F8 -> #REF! | J5: =I5/$I$3 -> #REF! | K5: ='P&L'!G8 -> #REF! | L5: =K5/$K$3 -> #REF!
B6: Pregnancy Powder- Trimester 3- Tier 1 | C6: ='P&L'!C9 | D6: =C6/$C$3 -> 0 | E6: ='P&L'!D9 -> #REF! | F6: =E6/$E$3 -> #REF! | G6: ='P&L'!E9 -> #REF! | H6: =G6/$G$3 -> #REF! | I6: ='P&L'!F9 -> #REF! | J6: =I6/$I$3 -> #REF! | K6: ='P&L'!G9 -> #REF! | L6: =K6/$K$3 -> #REF!
B7: Lactation Powder- Tier 1 | C7: ='P&L'!C10 | D7: =C7/$C$3 -> 0 | E7: ='P&L'!D10 -> 0 | F7: =E7/$E$3 -> #REF! | G7: ='P&L'!E10 -> 0 | H7: =G7/$G$3 -> #REF! | I7: ='P&L'!F10 -> 0 | J7: =I7/$I$3 -> #REF! | K7: ='P&L'!G10 -> 0 | L7: =K7/$K$3 -> #REF!
B8: Infant Formula Powder- 0 to 6m- Tier 1 | C8: ='P&L'!C11 | D8: =C8/$C$3 -> 0 | E8: ='P&L'!D11 -> #REF! | F8: =E8/$E$3 -> #REF! | G8: ='P&L'!E11 -> #REF! | H8: =G8/$G$3 -> #REF! | I8: ='P&L'!F11 -> #REF! | J8: =I8/$I$3 -> #REF! | K8: ='P&L'!G11 -> #REF! | L8: =K8/$K$3 -> #REF!
B9: Infant Formula Powder- 6 to 12m- Tier 1 | C9: ='P&L'!C12 | D9: =C9/$C$3 -> 0 | E9: ='P&L'!D12 -> #REF! | F9: =E9/$E$3 -> #REF! | G9: ='P&L'!E12 -> #REF! | H9: =G9/$G$3 -> #REF! | I9: ='P&L'!F12 -> #REF! | J9: =I9/$I$3 -> #REF! | K9: ='P&L'!G12 -> #REF! | L9: =K9/$K$3 -> #REF!
B10: Infant Formula Powder- 12 to 24m- Tier 1 | C10: ='P&L'!C13 | D10: =C10/$C$3 -> 0 | E10: ='P&L'!D13 -> #REF! | F10: =E10/$E$3 -> #REF! | G10: ='P&L'!E13 -> #REF! | H10: =G10/$G$3 -> #REF! | I10: ='P&L'!F13 -> #REF! | J10: =I10/$I$3 -> #REF! | K10: ='P&L'!G13 -> #REF! | L10: =K10/$K$3 -> #REF!
B11: Infant Complementary Food- 6 to 12m- Tier 1 | C11: ='P&L'!C14 | D11: =C11/$C$3 -> 0 | E11: ='P&L'!D14 -> #REF! | F11: =E11/$E$3 -> #REF! | G11: ='P&L'!E14 -> #REF! | H11: =G11/$G$3 -> #REF! | I11: ='P&L'!F14 -> #REF! | J11: =I11/$I$3 -> #REF! | K11: ='P&L'!G14 -> #REF! | L11: =K11/$K$3 -> #REF!
B12: Infant Complementary Food- 12 to 24m- Tier 1 | C12: ='P&L'!C15 | D12: =C12/$C$3 -> 0 | E12: ='P&L'!D15 -> #REF! | F12: =E12/$E$3 -> #REF! | G12: ='P&L'!E15 -> #REF! | H12: =G12/$G$3 -> #REF! | I12: ='P&L'!F15 -> #REF! | J12: =I12/$I$3 -> #REF! | K12: ='P&L'!G15 -> #REF! | L12: =K12/$K$3 -> #REF!
B13: Children Powder- Tier 1 | C13: ='P&L'!C16 | D13: =C13/$C$3 -> 0 | E13: ='P&L'!D16 -> 0 | F13: =E13/$E$3 -> #REF! | G13: ='P&L'!E16 -> 0 | H13: =G13/$G$3 -> #REF! | I13: ='P&L'!F16 -> 0 | J13: =I13/$I$3 -> #REF! | K13: ='P&L'!G16 -> 0 | L13: =K13/$K$3 -> #REF!
B14: Pregnancy Powder- Trimester 1- Tier 2 | C14: ='P&L'!C17 | D14: =C14/$C$3 -> 0 | E14: ='P&L'!D17 | F14: =E14/$E$3 -> #REF! | G14: ='P&L'!E17 -> 0 | H14: =G14/$G$3 -> #REF! | I14: ='P&L'!F17 -> 0 | J14: =I14/$I$3 -> #REF! | K14: ='P&L'!G17 -> 0 | L14: =K14/$K$3 -> #REF!
... B28: Contract Manufacturing | C28: ='P&L'!C31 | D28: =C28/$C$3 -> 0 | E28: ='P&L'!D31 -> #REF! | F28: =E28/$E$3 -> #REF! | G28: ='P&L'!E31 -> #REF! | H28: =G28/$G$3 -> #REF! | I28: ='P&L'!F31 -> #REF! | J28: =I28/$I$3 -> #REF! | K28: ='P&L'!G31 -> #REF! | L28: =K28/$K$3 -> #REF!
C30: 1 | E30: 2 | G30: 3 | I30: 4 | K30: 5
B31: Tier 1 | C31: =sum(C4:C13) -> 0 | D31: =sum(D4:D13) -> 0 | E31: =sum(E4:E13) -> #REF! | F31: =sum(F4:F13) -> #REF! | G31: =sum(G4:G13) -> #REF! | H31: =sum(H4:H13) -> #REF! | I31: =sum(I4:I13) -> #REF! | J31: =sum(J4:J13) -> #REF! | ... L31: =sum(L4:L13) -> #REF!
B32: Tier 2 | C32: =sum(C14:C23) -> 0 | D32: =sum(D14:D23) -> 0 | E32: =sum(E14:E23) -> 0 | F32: =sum(F14:F23) -> #REF! | G32: =sum(G14:G23) -> 0 | H32: =sum(H14:H23) -> #REF! | I32: =sum(I14:I23) -> 0 | J32: =sum(J14:J23) -> #REF! | ... L32: =sum(L14:L23) -> #REF!
B33: Tier 3 | C33: =sum(C24:C27) -> 88.413 | D33: =sum(D24:D27) -> 1 | E33: =sum(E24:E27) -> 0 | F33: =sum(F24:F27) -> #REF! | G33: =sum(G24:G27) -> 0 | H33: =sum(H24:H27) -> #REF! | I33: =sum(I24:I27) -> 0 | J33: =sum(J24:J27) -> #REF! | ... L33: =sum(L24:L27) -> #REF!
C35: 1 | D35: 2 | E35: 3 | F35: 4 | G35: 5
B36: Pregnancy Powder | C36: =sum($D$4:$D$6,$D$14:$D$16,$D$24) -> 0.2470225 | D36: =sum(F4:F6,F14:F16,F24) -> #REF! | E36: =sum(H4:H6,H14:H16,H24) -> #REF! | F36: =sum(J4:J6,J14:J16,J24) -> #REF! | G36: =sum(L4:L6,L14:L16,L24) -> #REF!
B37: Lactation Powder | C37: =sum($D$7,$D$17,$D$25) -> 0.25231584 | D37: =sum(F7,F17,F25) -> #REF! | E37: =sum(H7,H17,H25) -> #REF! | F37: =sum(J7,J17,J25) -> #REF! | G37: =sum(L7,L17,L25) -> #REF!
B38: Infant Powder | C38: =sum($D$8:$D$12,$D$18:$D$22,$D$26) -> 0.26687252 | D38: =sum(F8:F12,F18:F22,F26) -> #REF! | E38: =sum(H8:H12,H18:H22,H26) -> #REF! | F38: =sum(J8:J12,J18:J22,J26) -> #REF! | G38: =sum(L8:L12,L18:L22,L26) -> #REF!
B39: Children Powder | C39: =$D$13+$D$23+$D$27 -> 0.23378915 | D39: =F13+F23+F27 -> #REF! | E39: =H13+H23+H27 -> #REF! | F39: =J13+J23+J27 -> #REF! | G39: =L13+L23+L27 -> #REF!
B40: Total | C40: =sum(C36:C39) -> 1 | D40: =sum(D36:D39) -> #REF! | E40: =sum(E36:E39) -> #REF! | F40: =sum(F36:F39) -> #REF! | G40: =sum(G36:G39) -> #REF!
B41: Average | C41: =average(C36:C39) -> 0.25 | D41: =average(D36:D39) -> #REF! | E41: =average(E36:E39) -> #REF! | F41: =average(F36:F39) -> #REF! | G41: =average(G36:G39) -> #REF!
C43: 1 | D43: 2 | E43: 3 | F43: 4 | G43: 5
B44: Pregnancy Powder | C44: =VALUE(SUBSTITUTE(C36, "%", "")) -> 24.7 | D44: =VALUE(SUBSTITUTE(D36, "%", "")) -> #REF! | E44: =VALUE(SUBSTITUTE(E36, "%", "")) -> #REF! | F44: =VALUE(SUBSTITUTE(F36, "%", "")) -> #REF! | G44: =VALUE(SUBSTITUTE(G36, "%", "")) -> #REF!
B45: Lactation Powder | C45: =VALUE(SUBSTITUTE(C37, "%", "")) -> 25.2 | D45: =VALUE(SUBSTITUTE(D37, "%", "")) -> #REF! | E45: =VALUE(SUBSTITUTE(E37, "%", "")) -> #REF! | F45: =VALUE(SUBSTITUTE(F37, "%", "")) -> #REF! | G45: =VALUE(SUBSTITUTE(G37, "%", "")) -> #REF!
B46: Infant Powder | C46: =VALUE(SUBSTITUTE(C38, "%", "")) -> 26.7 | D46: =VALUE(SUBSTITUTE(D38, "%", "")) -> #REF! | E46: =VALUE(SUBSTITUTE(E38, "%", "")) -> #REF! | F46: =VALUE(SUBSTITUTE(F38, "%", "")) -> #REF! | G46: =VALUE(SUBSTITUTE(G38, "%", "")) -> #REF!
B47: Children Powder | C47: =VALUE(SUBSTITUTE(C39, "%", "")) -> 23.4 | D47: =VALUE(SUBSTITUTE(D39, "%", "")) -> #REF! | E47: =VALUE(SUBSTITUTE(E39, "%", "")) -> #REF! | F47: =VALUE(SUBSTITUTE(F39, "%", "")) -> #REF! | G47: =VALUE(SUBSTITUTE(G39, "%", "")) -> #REF!
C48: =sum(C44:C47) -> 100 | D48: =sum(D44:D47) -> #REF! | E48: =sum(E44:E47) -> #REF! | F48: =sum(F44:F47) -> #REF! | G48: =sum(G44:G47) -> #REF!

Sheet Indirect Expenses
B2: INDIRECT EXPENSE % BREAKUP TIER WISE & PRODUCT WISE
B3: Cost Head | C3: Remark | D3: Year 1 | G3: Year 2 | J3: Year 3 | M3: Year 4 | P3: Year 5
D4: Tier 1 (Metro) | E4: Tier 2 (Mid Cities) | F4: Tier 3 (Small Towns) | G4: Tier 1 (Metro) | H4: Tier 2 (Mid Cities) | I4: Tier 3 (Small Towns) | J4: Tier 1 (Metro) | K4: Tier 2 (Mid Cities) | L4: Tier 3 (Small Towns) | M4: Tier 1 (Metro) | N4: Tier 2 (Mid Cities) | O4: Tier 3 (Small Towns) | P4: Tier 1 (Metro) | Q4: Tier 2 (Mid Cities) | R4: Tier 3 (Small Towns)
B5: Marketing & Advertising (in %) | C5: * IMS Act prohibits infant formula consumer ads. Tier 1 budget shifts entirely to HCP detailing. 3 brand budgets from Y3. | D5: =VALUE(SUBSTITUTE('IE Biffurcation'!N13, "%", "")) -> 0 | E5: =VALUE(SUBSTITUTE('IE Biffurcation'!I13, "%", "")) -> 0 | F5: =VALUE(SUBSTITUTE('IE Biffurcation'!D13, "%", "")) -> 7 | G5: =VALUE(SUBSTITUTE('IE Biffurcation'!O13, "%", "")) -> 5 | H5: =VALUE(SUBSTITUTE('IE Biffurcation'!J13, "%", "")) -> 0 | I5: =VALUE(SUBSTITUTE('IE Biffurcation'!E13, "%", "")) -> 4 | J5: =VALUE(SUBSTITUTE('IE Biffurcation'!P13, "%", "")) -> 5 | K5: =VALUE(SUBSTITUTE('IE Biffurcation'!K13, "%", "")) -> 7 | L5: =VALUE(SUBSTITUTE('IE Biffurcation'!F13, "%", "")) -> 8 | M5: =VALUE(SUBSTITUTE('IE Biffurcation'!Q13, "%", "")) -> 6 | N5: =VALUE(SUBSTITUTE('IE Biffurcation'!L13, "%", "")) -> 6 | O5: =VALUE(SUBSTITUTE('IE Biffurcation'!G13, "%", "")) -> 5 | P5: =VALUE(SUBSTITUTE('IE Biffurcation'!R13, "%", "")) -> 3 | Q5: =VALUE(SUBSTITUTE('IE Biffurcation'!M13, "%", "")) -> 5 | R5: =VALUE(SUBSTITUTE('IE Biffurcation'!H13, "%", "")) -> 5
B6: Pregnancy Powder | D6: =D5 -> 0 | E6: =E5 -> 0 | F6: =$F$5*'Revenue Breakup'!C36 -> 1.7291575 | G6: =$G$5*('Revenue Breakup'!D36/'Revenue Breakup'!$D$40) -> #REF! | H6: =H5 -> 0 | I6: =$I$5*('Revenue Breakup'!D36/'Revenue Breakup'!$D$40) -> #REF! | J6: =$J$5*('Revenue Breakup'!E36/'Revenue Breakup'!$E$40) -> #REF! | K6: =$K$5*('Revenue Breakup'!E36/'Revenue Breakup'!$E$40) -> #REF! | L6: =$L$5*('Revenue Breakup'!E36/'Revenue Breakup'!$E$40) -> #REF! | M6: =$M$5*('Revenue Breakup'!F36/'Revenue Breakup'!$F$40) -> #REF! | N6: =$N$5*('Revenue Breakup'!F36/'Revenue Breakup'!$F$40) -> #REF! | O6: =$O$5*('Revenue Breakup'!F36/'Revenue Breakup'!$F$40) -> #REF! | P6: =$P$5*('Revenue Breakup'!G36/'Revenue Breakup'!$G$40) -> #REF! | Q6: =$Q$5*('Revenue Breakup'!G36/'Revenue Breakup'!$G$40) -> #REF! | R6: =$R$5*('Revenue Breakup'!G36/'Revenue Breakup'!$G$40) -> #REF!
B7: Lactation Powder | D7: =D6 -> 0 | E7: =E6 -> 0 | F7: =$F$5*'Revenue Breakup'!C37 -> 1.7662109 | G7: =$G$5*('Revenue Breakup'!D37/'Revenue Breakup'!$D$40) -> #REF! | H7: =H6 -> 0 | I7: =$I$5*('Revenue Breakup'!D37/'Revenue Breakup'!$D$40) -> #REF! | J7: =$J$5*('Revenue Breakup'!E37/'Revenue Breakup'!$E$40) -> #REF! | K7: =$K$5*('Revenue Breakup'!E37/'Revenue Breakup'!$E$40) -> #REF! | L7: =$L$5*('Revenue Breakup'!E37/'Revenue Breakup'!$E$40) -> #REF! | M7: =$M$5*('Revenue Breakup'!F37/'Revenue Breakup'!$F$40) -> #REF! | N7: =$N$5*('Revenue Breakup'!F37/'Revenue Breakup'!$F$40) -> #REF! | O7: =$O$5*('Revenue Breakup'!F37/'Revenue Breakup'!$F$40) -> #REF! | P7: =$P$5*('Revenue Breakup'!G37/'Revenue Breakup'!$G$40) -> #REF! | Q7: =$Q$5*('Revenue Breakup'!G37/'Revenue Breakup'!$G$40) -> #REF! | R7: =$R$5*('Revenue Breakup'!G37/'Revenue Breakup'!$G$40) -> #REF!
B8: Infant Powder | D8: =D7 -> 0 | E8: =E7 -> 0 | F8: =$F$5*'Revenue Breakup'!C38 -> 1.8681076 | G8: =$G$5*('Revenue Breakup'!D38/'Revenue Breakup'!$D$40) -> #REF! | H8: =H7 -> 0 | I8: =$I$5*('Revenue Breakup'!D38/'Revenue Breakup'!$D$40) -> #REF! | J8: =$J$5*('Revenue Breakup'!E38/'Revenue Breakup'!$E$40) -> #REF! | K8: =$K$5*('Revenue Breakup'!E38/'Revenue Breakup'!$E$40) -> #REF! | L8: =$L$5*('Revenue Breakup'!E38/'Revenue Breakup'!$E$40) -> #REF! | M8: =$M$5*('Revenue Breakup'!F38/'Revenue Breakup'!$F$40) -> #REF! | N8: =$N$5*('Revenue Breakup'!F38/'Revenue Breakup'!$F$40) -> #REF! | O8: =$O$5*('Revenue Breakup'!F38/'Revenue Breakup'!$F$40) -> #REF! | P8: =$P$5*('Revenue Breakup'!G38/'Revenue Breakup'!$G$40) -> #REF! | Q8: =$Q$5*('Revenue Breakup'!G38/'Revenue Breakup'!$G$40) -> #REF! | R8: =$R$5*('Revenue Breakup'!G38/'Revenue Breakup'!$G$40) -> #REF!
B9: Children Powder | D9: =D8 -> 0 | E9: =E8 -> 0 | F9: =$F$5*'Revenue Breakup'!C39 -> 1.636524 | G9: =$G$5*('Revenue Breakup'!D39/'Revenue Breakup'!$D$40) -> #REF! | H9: =H8 -> 0 | I9: =$I$5*('Revenue Breakup'!D39/'Revenue Breakup'!$D$40) -> #REF! | J9: =$J$5*('Revenue Breakup'!E39/'Revenue Breakup'!$E$40) -> #REF! | K9: =$K$5*('Revenue Breakup'!E39/'Revenue Breakup'!$E$40) -> #REF! | L9: =$L$5*('Revenue Breakup'!E39/'Revenue Breakup'!$E$40) -> #REF! | M9: =$M$5*('Revenue Breakup'!F39/'Revenue Breakup'!$F$40) -> #REF! | N9: =$N$5*('Revenue Breakup'!F39/'Revenue Breakup'!$F$40) -> #REF! | O9: =$O$5*('Revenue Breakup'!F39/'Revenue Breakup'!$F$40) -> #REF! | P9: =$P$5*('Revenue Breakup'!G39/'Revenue Breakup'!$G$40) -> #REF! | Q9: =$Q$5*('Revenue Breakup'!G39/'Revenue Breakup'!$G$40) -> #REF! | R9: =$R$5*('Revenue Breakup'!G39/'Revenue Breakup'!$G$40) -> #REF!
B10: HCP Detailing & Medical Engagement (in %) | C10: * OBGYNs, pediatricians, hospitals drive prescription/recommendation. Mandatory for infant formula category growth. | D10: =VALUE(SUBSTITUTE('IE Biffurcation'!N20, "%", "")) -> 0 | E10: =VALUE(SUBSTITUTE('IE Biffurcation'!I20, "%", "")) -> 0 | F10: =VALUE(SUBSTITUTE('IE Biffurcation'!D20, "%", "")) -> 2 | G10: =VALUE(SUBSTITUTE('IE Biffurcation'!O20, "%", "")) -> 3 | H10: =VALUE(SUBSTITUTE('IE Biffurcation'!J20, "%", "")) -> 0 | I10: =VALUE(SUBSTITUTE('IE Biffurcation'!E20, "%", "")) -> 2 | J10: =VALUE(SUBSTITUTE('IE Biffurcation'!P20, "%", "")) -> 5 | K10: =VALUE(SUBSTITUTE('IE Biffurcation'!K20, "%", "")) -> 3 | L10: =VALUE(SUBSTITUTE('IE Biffurcation'!F20, "%", "")) -> 2 | M10: =VALUE(SUBSTITUTE('IE Biffurcation'!Q20, "%", "")) -> 5 | N10: =VALUE(SUBSTITUTE('IE Biffurcation'!L20, "%", "")) -> 4 | O10: =VALUE(SUBSTITUTE('IE Biffurcation'!G20, "%", "")) -> 4 | P10: =VALUE(SUBSTITUTE('IE Biffurcation'!R20, "%", "")) -> 6 | Q10: =VALUE(SUBSTITUTE('IE Biffurcation'!M20, "%", "")) -> 5 | R10: =VALUE(SUBSTITUTE('IE Biffurcation'!H20, "%", "")) -> 4
B11: Pregnancy Powder | D11: =D10 -> 0 | E11: =E10 -> 0 | F11: =$F$10*'Revenue Breakup'!C36 -> 0.49404499 | G11: =$G$10*('Revenue Breakup'!D36/'Revenue Breakup'!$D$40) -> #REF! | H11: =H10 -> 0 | I11: =$I$10*('Revenue Breakup'!D36/'Revenue Breakup'!$D$40) -> #REF! | J11: =$J$10*('Revenue Breakup'!E36/'Revenue Breakup'!$E$40) -> #REF! | K11: =$K$10*('Revenue Breakup'!E36/'Revenue Breakup'!$E$40) -> #REF! | L11: =$L$10*('Revenue Breakup'!E36/'Revenue Breakup'!$E$40) -> #REF! | M11: =$M$10*('Revenue Breakup'!F36/'Revenue Breakup'!$F$40) -> #REF! | N11: =$N$10*('Revenue Breakup'!F36/'Revenue Breakup'!$F$40) -> #REF! | O11: =$O$10*('Revenue Breakup'!F36/'Revenue Breakup'!$F$40) -> #REF! | P11: =$P$10*('Revenue Breakup'!G36/'Revenue Breakup'!$G$40) -> #REF! | Q11: =$Q$10*('Revenue Breakup'!G36/'Revenue Breakup'!$G$40) -> #REF! | R11: =$R$10*('Revenue Breakup'!G36/'Revenue Breakup'!$G$40) -> #REF!
B12: Lactation Powder | D12: =D11 -> 0 | E12: =E11 -> 0 | F12: =$F$10*'Revenue Breakup'!C37 -> 0.50463167 | G12: =$G$10*('Revenue Breakup'!D37/'Revenue Breakup'!$D$40) -> #REF! | H12: =H11 -> 0 | I12: =$I$10*('Revenue Breakup'!D37/'Revenue Breakup'!$D$40) -> #REF! | J12: =$J$10*('Revenue Breakup'!E37/'Revenue Breakup'!$E$40) -> #REF! | K12: =$K$10*('Revenue Breakup'!E37/'Revenue Breakup'!$E$40) -> #REF! | L12: =$L$10*('Revenue Breakup'!E37/'Revenue Breakup'!$E$40) -> #REF! | M12: =$M$10*('Revenue Breakup'!F37/'Revenue Breakup'!$F$40) -> #REF! | N12: =$N$10*('Revenue Breakup'!F37/'Revenue Breakup'!$F$40) -> #REF! | O12: =$O$10*('Revenue Breakup'!F37/'Revenue Breakup'!$F$40) -> #REF! | P12: =$P$10*('Revenue Breakup'!G37/'Revenue Breakup'!$G$40) -> #REF! | Q12: =$Q$10*('Revenue Breakup'!G37/'Revenue Breakup'!$G$40) -> #REF! | R12: =$R$10*('Revenue Breakup'!G37/'Revenue Breakup'!$G$40) -> #REF!
B13: Infant Powder | D13: =D12 -> 0 | E13: =E12 -> 0 | F13: =$F$10*'Revenue Breakup'!C38 -> 0.53374504 | G13: =$G$10*('Revenue Breakup'!D38/'Revenue Breakup'!$D$40) -> #REF! | H13: =H12 -> 0 | I13: =$I$10*('Revenue Breakup'!D38/'Revenue Breakup'!$D$40) -> #REF! | J13: =$J$10*('Revenue Breakup'!E38/'Revenue Breakup'!$E$40) -> #REF! | K13: =$K$10*('Revenue Breakup'!E38/'Revenue Breakup'!$E$40) -> #REF! | L13: =$L$10*('Revenue Breakup'!E38/'Revenue Breakup'!$E$40) -> #REF! | M13: =$M$10*('Revenue Breakup'!F38/'Revenue Breakup'!$F$40) -> #REF! | N13: =$N$10*('Revenue Breakup'!F38/'Revenue Breakup'!$F$40) -> #REF! | O13: =$O$10*('Revenue Breakup'!F38/'Revenue Breakup'!$F$40) -> #REF! | P13: =$P$10*('Revenue Breakup'!G38/'Revenue Breakup'!$G$40) -> #REF! | Q13: =$Q$10*('Revenue Breakup'!G38/'Revenue Breakup'!$G$40) -> #REF! | R13: =$R$10*('Revenue Breakup'!G38/'Revenue Breakup'!$G$40) -> #REF!
